Workbook

Sheet Cover
C3: TATA CONSULTANCY SERVICES LIMITED (NSE/BSE: TCS)
C4: Integrated Financial Model & Intrinsic Valuation
C5: Three-Statement Model | DCF (FCFF) Valuation | Relative Valuation | Ratio Analysis
C8: Prepared for: Independent Equity Research / Illustrative Purposes
C9: Prepared: July 2026
C10: Currency: Indian Rupees (₹), figures in Crore (1 Cr = 10 million) unless stated otherwise
C11: Fiscal Year End: 31 March
C13: SNAPSHOT
C14: Current Market Price (₹) | E14: 2093.5
C15: Shares Outstanding (Cr) | E15: 361.81
C16: Market Capitalization (₹ Cr) | E16: 757446.62
C17: 52-Week Range / Sector | E17: IT Services — Nifty IT
C19: CONTENTS
C20: 1. Assumptions & Cost of Capital
C21: 2. Income Statement
C22: 3. Balance Sheet
C23: 4. Cash Flow Statement
C24: 5. Ratio Analysis
C25: 6. DCF Valuation (FCFF)
C26: 7. Relative Valuation (Comps)
C27: 8. Dashboard & Football Field
C29: Color Legend: Blue = hardcoded input / historical actual figure. Black = formula / calculation. Green = link pulling from another worksheet. Disclaimer: This model is built from publicly available historical financial data and is intended for illustrative / educational purposes. Projections and assumptions (growth, margins, WACC inputs) are estimates and should be independently verified before use in an investment decision. This is not investment advice.

Sheet Assumptions
A1: TCS — Model Assumptions & Cost of Capital
A2: Historical ratios are calculated from reported financials (green). Projection-period cells in blue are analyst inputs — change them to run scenarios.
A4: 1. OPERATING & WORKING CAPITAL ASSUMPTIONS (₹ Crore basis, ratios shown as %)
A5: (₹ Crore, unless stated otherwise) | B5: FY2017 | C5: FY2018 | D5: FY2019 | E5: FY2020 | F5: FY2021 | G5: FY2022 | H5: FY2023 | I5: FY2024 | J5: FY2025 | K5: FY2026 | L5: FY2027E | M5: FY2028E | N5: FY2029E | O5: FY2030E | P5: FY2031E
A6: Revenue growth % (YoY) | C6: =IFERROR(IS!C6/IS!B6-1,"") -> 0.043554923 | D6: =IFERROR(IS!D6/IS!C6-1,"") -> 0.18975013 | E6: =IFERROR(IS!E6/IS!D6-1,"") -> 0.071594874 | F6: =IFERROR(IS!F6/IS!E6-1,"") -> 0.046053177 | G6: =IFERROR(IS!G6/IS!F6-1,"") -> 0.16797115 | H6: =IFERROR(IS!H6/IS!G6-1,"") -> 0.17576687 | I6: =IFERROR(IS!I6/IS!H6-1,"") -> 0.068460645 | J6: =IFERROR(IS!J6/IS!I6-1,"") -> 0.059906265 | K6: =IFERROR(IS!K6/IS!J6-1,"") -> 0.04581238 | L6: 0.07 | M6: 0.075 | N6: 0.08 | O6: 0.08 | P6: 0.08
A7: EBITDA margin % | B7: =IS!B15/IS!B6 -> 0.27389248 | C7: =IS!C15/IS!C6 -> 0.26413439 | D7: =IS!D15/IS!D6 -> 0.26973365 | E7: =IS!E15/IS!E6 -> 0.26829734 | F7: =IS!F15/IS!F6 -> 0.28351109 | G7: =IS!G15/IS!G6 -> 0.27669305 | H7: =IS!H15/IS!H6 -> 0.26283831 | I7: =IS!I15/IS!I6 -> 0.26690688 | ... K7: =IS!K15/IS!K6 -> 0.27113223 | L7: 0.265 | M7: 0.27 | N7: 0.27 | O7: 0.275 | P7: 0.275
A8: Depreciation & amortization (% of sales) | B8: =IS!B18/IS!B6 -> 0.016843836 | C8: =IS!C18/IS!C6 -> 0.016360151 | D8: =IS!D18/IS!D6 -> 0.014037675 | E8: =IS!E18/IS!E6 -> 0.022485011 | F8: =IS!F18/IS!F6 -> 0.024759863 | G8: =IS!G18/IS!G6 -> 0.024009929 | H8: =IS!H18/IS!H6 -> 0.022274659 | I8: =IS!I18/IS!I6 -> 0.020693835 | ... K8: =IS!K18/IS!K6 -> 0.020822332 | L8: 0.022 | M8: 0.022 | N8: 0.022 | O8: 0.022 | P8: 0.022
A9: Capital expenditure (% of sales) | C9: =IFERROR(((BS!C6+BS!C7)-(BS!B6+BS!B7)+IS!C18)/IS!C6,"") -> 0.01643326 | D9: =IFERROR(((BS!D6+BS!D7)-(BS!C6+BS!C7)+IS!D18)/IS!D6,"") -> 0.01405133 | E9: =IFERROR(((BS!E6+BS!E7)-(BS!D6+BS!D7)+IS!E18)/IS!E6,"") -> 0.077158822 | F9: =IFERROR(((BS!F6+BS!F7)-(BS!E6+BS!E7)+IS!F18)/IS!F6,"") -> 0.025448144 | G9: =IFERROR(((BS!G6+BS!G7)-(BS!F6+BS!F7)+IS!G18)/IS!G6,"") -> 0.026909478 | H9: =IFERROR(((BS!H6+BS!H7)-(BS!G6+BS!G7)+IS!H18)/IS!H6,"") -> 0.018930355 | I9: =IFERROR(((BS!I6+BS!I7)-(BS!H6+BS!H7)+IS!I18)/IS!I6,"") -> 0.018281976 | J9: =IFERROR(((BS!J6+BS!J7)-(BS!I6+BS!I7)+IS!J18)/IS!J6,"") -> 0.033968605 | K9: =IFERROR(((BS!K6+BS!K7)-(BS!J6+BS!J7)+IS!K18)/IS!K6,"") -> 0.056059261 | L9: 0.045 | M9: 0.045 | N9: 0.04 | O9: 0.04 | P9: 0.04
A10: Effective tax rate % | B10: =IS!B22/IS!B21 -> 0.2363236 | C10: =IS!C22/IS!C21 -> 0.24087763 | D10: =IS!D22/IS!D21 -> 0.24062267 | E10: =IS!E22/IS!E21 -> 0.23198731 | F10: =IS!F22/IS!F21 -> 0.2558958 | G10: =IS!G22/IS!G21 -> 0.25611856 | H10: =IS!H22/IS!H21 -> 0.25662924 | I10: =IS!I22/IS!I21 -> 0.25643176 | ... K10: =IS!K22/IS!K21 -> 0.24482722 | L10: 0.25 | M10: 0.25 | N10: 0.25 | O10: 0.25 | P10: 0.25
A11: Receivable days (DSO) | B11: =BS!B9/IS!B6*365 -> 69.979528 | C11: =BS!C9/IS!C6*365 -> 73.955314 | D11: =BS!D9/IS!D6*365 -> 68.148884 | E11: =BS!E9/IS!E6*365 -> 71.005104 | F11: =BS!F9/IS!F6*365 -> 66.871943 | G11: =BS!G9/IS!G6*365 -> 79.58452 | H11: =BS!H9/IS!H6*365 -> 80.87187 | I11: =BS!I9/IS!I6*365 -> 81.179632 | ... K11: =BS!K9/IS!K6*365 -> 92.560548 | L11: 92 | M11: 91 | N11: 90 | O11: 90 | P11: 90
A12: Other liabilities (% of sales) | B12: =BS!B19/IS!B6 -> 0.13419121 | C12: =BS!C19/IS!C6 -> 0.16044158 | D12: =BS!D19/IS!D6 -> 0.16654718 | E12: =BS!E19/IS!E6 -> 0.17729963 | F12: =BS!F19/IS!F6 -> 0.21783807 | G12: =BS!G19/IS!G6 -> 0.22928857 | H12: =BS!H19/IS!H6 -> 0.19847156 | I12: =BS!I19/IS!I6 -> 0.19494962 | ... K12: =BS!K19/IS!K6 -> 0.23460327 | L12: 0.234 | M12: 0.234 | N12: 0.234 | O12: 0.234 | P12: 0.234
A13: Other assets, net (% of sales) | B13: =BS!B12/IS!B6 -> 0.17228693 | C13: =BS!C12/IS!C6 -> 0.1928207 | D13: =BS!D12/IS!D6 -> 0.21243591 | E13: =BS!E12/IS!E6 -> 0.20219307 | F13: =BS!F12/IS!F6 -> 0.23910779 | G13: =BS!G12/IS!G6 -> 0.1454207 | H13: =BS!H12/IS!H6 -> 0.10171739 | I13: =BS!I12/IS!I6 -> 0.10648296 | ... K13: =BS!K12/IS!K6 -> 0.12178817 | L13: 0.122 | M13: 0.122 | N13: 0.122 | O13: 0.122 | P13: 0.122
A14: Dividend payout ratio (% of PAT) | B14: =IS!B26/IS!B24 -> 0.35130521 | C14: =IS!C26/IS!C24 -> 0.36901082 | D14: =IS!D26/IS!D24 -> 0.35644129 | E14: =IS!E26/IS!E24 -> 0.84368355 | F14: =IS!F26/IS!F24 -> 0.43179166 | G14: =IS!G26/IS!G24 -> 0.40932144 | H14: =IS!H26/IS!H24 -> 0.9949649 | I14: =IS!I26/IS!I24 -> 0.57324454 | ... K14: =IS!K26/IS!K24 -> 0.8051927 | L14: 0.8 | M14: 0.8 | N14: 0.8 | O14: 0.8 | P14: 0.8
A15: Interest rate on borrowings (%) | C15: =IFERROR(IS!C20/AVERAGE(BS!B18,BS!C18),"") -> 0.19402985 | D15: =IFERROR(IS!D20/AVERAGE(BS!C18,BS!D18),"") -> 1.2815534 | E15: =IFERROR(IS!E20/AVERAGE(BS!D18,BS!E18),"") -> 0.22438077 | F15: =IFERROR(IS!F20/AVERAGE(BS!E18,BS!F18),"") -> 0.079779573 | G15: =IFERROR(IS!G20/AVERAGE(BS!F18,BS!G18),"") -> 0.10042913 | H15: =IFERROR(IS!H20/AVERAGE(BS!G18,BS!H18),"") -> 0.10047723 | I15: =IFERROR(IS!I20/AVERAGE(BS!H18,BS!I18),"") -> 0.099051499 | J15: =IFERROR(IS!J20/AVERAGE(BS!I18,BS!J18),"") -> 0.091425946 | K15: =IFERROR(IS!K20/AVERAGE(BS!J18,BS!K18),"") -> 0.11869407 | L15: 0.075 | M15: 0.075 | N15: 0.075 | O15: 0.075 | P15: 0.075
A16: Yield on cash & investments (%) | C16: =IFERROR(IS!C17/AVERAGE(BS!B11+BS!B8,BS!C11+BS!C8),"") -> 0.081569576 | D16: =IFERROR(IS!D17/AVERAGE(BS!C11+BS!C8,BS!D11+BS!D8),"") -> 0.10102288 | E16: =IFERROR(IS!E17/AVERAGE(BS!D11+BS!D8,BS!E11+BS!E8),"") -> 0.11744246 | F16: =IFERROR(IS!F17/AVERAGE(BS!E11+BS!E8,BS!F11+BS!F8),"") -> 0.051282051 | G16: =IFERROR(IS!G17/AVERAGE(BS!F11+BS!F8,BS!G11+BS!G8),"") -> 0.091936665 | H16: =IFERROR(IS!H17/AVERAGE(BS!G11+BS!G8,BS!H11+BS!H8),"") -> 0.071186056 | I16: =IFERROR(IS!I17/AVERAGE(BS!H11+BS!H8,BS!I11+BS!I8),"") -> 0.074300484 | J16: =IFERROR(IS!J17/AVERAGE(BS!I11+BS!I8,BS!J11+BS!J8),"") -> 0.086624761 | K16: =IFERROR(IS!K17/AVERAGE(BS!J11+BS!J8,BS!K11+BS!K8),"") -> -0.0026574371 | L16: 0.062 | M16: 0.062 | N16: 0.062 | O16: 0.062 | P16: 0.062
A18: 2. COST OF CAPITAL (WACC) — SINGLE-POINT INPUTS
A19: Risk-free rate (India 10-Yr G-Sec yield) | C19: 0.0675
A20: Equity risk premium (India) | C20: 0.065
A21: Levered beta | C21: 0.9
A22: Cost of equity (CAPM) = Rf + β × ERP | C22: =C19+C21*C20 -> 0.126
A23: Pre-tax cost of debt | C23: 0.075
A24: Tax rate (for WACC) | C24: =K10 -> 0.24482722
A25: After-tax cost of debt | C25: =C23*(1-C24) -> 0.056637959
A26: Market value of equity (current market cap, ₹ Cr) | C26: =C36 -> 757449.23
A27: Total debt (FY2026A, ₹ Cr) | C27: =BS!K18 -> 11283
A28: Weight of equity | C28: =C26/(C26+C27) -> 0.98532259
A29: Weight of debt | C29: =C27/(C26+C27) -> 0.014677412
A30: WACC | C30: =C28*C22+C29*C25 -> 0.12498194
A32: Terminal growth rate (g) | C32: 0.05
A34: 3. CURRENT MARKET DATA
A35: Current share price (₹) | C35: 2093.5
A36: Market capitalization (₹ Cr) | C36: =C35*C37 -> 757449.23
A37: Shares outstanding (Cr) | C37: 361.81
A38: Face value per share (₹) | C38: 1

Sheet IS
A1: Income Statement
A2: Tata Consultancy Services Ltd. (Consolidated)
A4: INCOME STATEMENT
A5: (₹ Crore, unless stated otherwise) | B5: FY2017 | C5: FY2018 | D5: FY2019 | E5: FY2020 | F5: FY2021 | G5: FY2022 | H5: FY2023 | I5: FY2024 | J5: FY2025 | K5: FY2026 | L5: FY2027E | M5: FY2028E | N5: FY2029E | O5: FY2030E | P5: FY2031E
A6: Revenue from Operations | B6: 117966 | C6: 123104 | D6: 146463 | E6: 156949 | F6: 164177 | G6: 191754 | H6: 225458 | I6: 240893 | J6: 255324 | K6: 267021 | L6: =IS!K6*(1+Assumptions!L6) -> 285712.47 | M6: =IS!L6*(1+Assumptions!M6) -> 307140.91 | N6: =IS!M6*(1+Assumptions!N6) -> 331712.18 | O6: =IS!N6*(1+Assumptions!O6) -> 358249.15 | P6: =IS!O6*(1+Assumptions!P6) -> 386909.08
A7: Growth % YoY | C7: =IFERROR(C6/B6-1,"") -> 0.043554923 | D7: =IFERROR(D6/C6-1,"") -> 0.18975013 | E7: =IFERROR(E6/D6-1,"") -> 0.071594874 | F7: =IFERROR(F6/E6-1,"") -> 0.046053177 | G7: =IFERROR(G6/F6-1,"") -> 0.16797115 | H7: =IFERROR(H6/G6-1,"") -> 0.17576687 | I7: =IFERROR(I6/H6-1,"") -> 0.068460645 | J7: =IFERROR(J6/I6-1,"") -> 0.059906265 | ... P7: =IFERROR(P6/O6-1,"") -> 0.08
A9: Operating Expenses
A10: Employee Costs | B10: 61621 | C10: 66396 | D10: 78246 | E10: 85952 | F10: 91814 | G10: 107554 | H10: 127522 | I10: 140131 | J10: 145788 | K10: 154994 | L10: n/a — modeled at aggregate EBITDA margin (see row 14) | M10: n/a — modeled at aggregate EBITDA margin (see row 14) | N10: n/a — modeled at aggregate EBITDA margin (see row 14) | O10: n/a — modeled at aggregate EBITDA margin (see row 14) | P10: n/a — modeled at aggregate EBITDA margin (see row 14)
A11: Cost of Materials & Other Direct Costs | B11: 2809 | C11: 2700 | D11: 2270 | E11: 1905 | F11: 1462 | G11: 1163 | H11: 1881 | I11: 3702 | J11: 11648 | K11: 4399 | L11: n/a — modeled at aggregate EBITDA margin (see row 14) | M11: n/a — modeled at aggregate EBITDA margin (see row 14) | N11: n/a — modeled at aggregate EBITDA margin (see row 14) | O11: n/a — modeled at aggregate EBITDA margin (see row 14) | P11: n/a — modeled at aggregate EBITDA margin (see row 14)
A12: Selling, General & Admin. Expenses | B12: 16392 | C12: 16808 | D12: 20387 | E12: 20527 | F12: 18322 | G12: 23187 | H12: 28913 | I12: 24151 | J12: 20729 | K12: 24434 | L12: n/a — modeled at aggregate EBITDA margin (see row 14) | M12: n/a — modeled at aggregate EBITDA margin (see row 14) | N12: n/a — modeled at aggregate EBITDA margin (see row 14) | O12: n/a — modeled at aggregate EBITDA margin (see row 14) | P12: n/a — modeled at aggregate EBITDA margin (see row 14)
A13: Other Expenses | B13: 4834 | C13: 4684 | D13: 6054 | E13: 6456 | F13: 6033 | G13: 6793 | H13: 7883 | I13: 8613 | J13: 9752 | K13: 10796 | L13: n/a — modeled at aggregate EBITDA margin (see row 14) | M13: n/a — modeled at aggregate EBITDA margin (see row 14) | N13: n/a — modeled at aggregate EBITDA margin (see row 14) | O13: n/a — modeled at aggregate EBITDA margin (see row 14) | P13: n/a — modeled at aggregate EBITDA margin (see row 14)
A14: Total Operating Expenses | B14: =SUM(B10:B13) -> 85656 | C14: =SUM(C10:C13) -> 90588 | D14: =SUM(D10:D13) -> 106957 | E14: =SUM(E10:E13) -> 114840 | F14: =SUM(F10:F13) -> 117631 | G14: =SUM(G10:G13) -> 138697 | H14: =SUM(H10:H13) -> 166199 | I14: =SUM(I10:I13) -> 176597 | ... K14: =SUM(K10:K13) -> 194623 | L14: =IS!L6*(1-Assumptions!L7) -> 209998.67 | M14: =IS!M6*(1-Assumptions!M7) -> 224212.86 | N14: =IS!N6*(1-Assumptions!N7) -> 242149.89 | O14: =IS!O6*(1-Assumptions!O7) -> 259730.64 | P14: =IS!P6*(1-Assumptions!P7) -> 280509.09
A15: EBITDA | B15: =B6-B14 -> 32310 | C15: =C6-C14 -> 32516 | D15: =D6-D14 -> 39506 | E15: =E6-E14 -> 42109 | F15: =F6-F14 -> 46546 | G15: =G6-G14 -> 53057 | H15: =H6-H14 -> 59259 | I15: =I6-I14 -> 64296 | ... P15: =P6-P14 -> 106400
A16: EBITDA Margin % | B16: =B15/B6 -> 0.27389248 | C16: =C15/C6 -> 0.26413439 | D16: =D15/D6 -> 0.26973365 | E16: =E15/E6 -> 0.26829734 | F16: =F15/F6 -> 0.28351109 | G16: =G15/G6 -> 0.27669305 | H16: =H15/H6 -> 0.26283831 | I16: =I15/I6 -> 0.26690688 | ... P16: =P15/P6 -> 0.275
A17: Other Income | B17: 4221 | C17: 3642 | D17: 4311 | E17: 4592 | F17: 1916 | G17: 4018 | H17: 3449 | I17: 3464 | J17: 3962 | K17: -124 | L17: =Assumptions!L16*(BS!K11+BS!K8) -> 2907.552 | M17: =Assumptions!M16*(BS!L11+BS!L8) -> 3014.6031 | N17: =Assumptions!N16*(BS!M11+BS!M8) -> 3171.2761 | O17: =Assumptions!O16*(BS!N11+BS!N8) -> 3434.9265 | P17: =Assumptions!P16*(BS!O11+BS!O8) -> 3680.704
A18: Less: Depreciation & Amortization | B18: 1987 | C18: 2014 | D18: 2056 | E18: 3529 | F18: 4065 | G18: 4604 | H18: 5022 | I18: 4985 | J18: 5242 | K18: 5560 | L18: =Assumptions!L8*L6 -> 6285.6743 | M18: =Assumptions!M8*M6 -> 6757.0999 | N18: =Assumptions!N8*N6 -> 7297.6679 | O18: =Assumptions!O8*O6 -> 7881.4813 | P18: =Assumptions!P8*P6 -> 8511.9998
A19: EBIT | B19: =B15-B18 -> 30323 | C19: =C15-C18 -> 30502 | D19: =D15-D18 -> 37450 | E19: =E15-E18 -> 38580 | F19: =F15-F18 -> 42481 | G19: =G15-G18 -> 48453 | H19: =H15-H18 -> 54237 | I19: =I15-I18 -> 59311 | ... P19: =P15-P18 -> 97887.998
A20: Less: Interest Expense | B20: 32 | C20: 52 | D20: 198 | E20: 924 | F20: 637 | G20: 784 | H20: 779 | I20: 778 | J20: 796 | K20: 1227 | L20: =Assumptions!L15*BS!K18 -> 846.225 | M20: =Assumptions!M15*BS!L18 -> 846.225 | N20: =Assumptions!N15*BS!M18 -> 846.225 | O20: =Assumptions!O15*BS!N18 -> 846.225 | P20: =Assumptions!P15*BS!O18 -> 846.225
A21: Profit Before Tax (PBT) | B21: =B19+B17-B20 -> 34512 | C21: =C19+C17-C20 -> 34092 | D21: =D19+D17-D20 -> 41563 | E21: =E19+E17-E20 -> 42248 | F21: =F19+F17-F20 -> 43760 | G21: =G19+G17-G20 -> 51687 | H21: =H19+H17-H20 -> 56907 | I21: =I19+I17-I20 -> 61997 | ... P21: =P19+P17-P20 -> 100722.48
A22: Less: Tax Expense | B22: 8156 | C22: 8212 | D22: 10001 | E22: 9801 | F22: 11198 | G22: 13238 | H22: 14604 | I22: 15898 | J22: 16534 | K22: 16033 | L22: =Assumptions!L10*L21 -> 17872.364 | M22: =Assumptions!M10*M21 -> 19584.831 | N22: =Assumptions!N10*N21 -> 21147.418 | O22: =Assumptions!O10*O21 -> 23306.434 | P22: =Assumptions!P10*P21 -> 25180.619
A23: Effective Tax Rate % | B23: =B22/B21 -> 0.2363236 | C23: =C22/C21 -> 0.24087763 | D23: =D22/D21 -> 0.24062267 | E23: =E22/E21 -> 0.23198731 | F23: =F22/F21 -> 0.2558958 | G23: =G22/G21 -> 0.25611856 | H23: =H22/H21 -> 0.25662924 | I23: =I22/I21 -> 0.25643176 | ... P23: =P22/P21 -> 0.25
A24: Net Profit After Tax (PAT) | B24: =B21-B22 -> 26356 | C24: =C21-C22 -> 25880 | D24: =D21-D22 -> 31562 | E24: =E21-E22 -> 32447 | F24: =F21-F22 -> 32562 | G24: =G21-G22 -> 38449 | H24: =H21-H22 -> 42303 | I24: =I21-I22 -> 46099 | ... P24: =P21-P22 -> 75541.858
A25: Net Profit Margin % | B25: =B24/B6 -> 0.22342031 | C25: =C24/C6 -> 0.21022875 | D25: =D24/D6 -> 0.2154947 | E25: =E24/E6 -> 0.20673595 | F25: =F24/F6 -> 0.19833472 | G25: =G24/G6 -> 0.20051211 | H25: =H24/H6 -> 0.1876314 | I25: =I24/I6 -> 0.19136712 | ... P25: =P24/P6 -> 0.19524447
A26: Dividends Paid | B26: 9259 | C26: 9550 | D26: 11250 | E26: 27375 | F26: 14060 | G26: 15738 | H26: 42090 | I26: 26426 | J26: 45612 | K26: 39820 | L26: =Assumptions!L14*L24 -> 42893.674 | M26: =Assumptions!M14*M24 -> 47003.594 | N26: =Assumptions!N14*N24 -> 50753.803 | O26: =Assumptions!O14*O24 -> 55935.442 | P26: =Assumptions!P14*P24 -> 60433.486
A27: Retained Earnings | B27: =B24-B26 -> 17097 | C27: =C24-C26 -> 16330 | D27: =D24-D26 -> 20312 | E27: =E24-E26 -> 5072 | F27: =F24-F26 -> 18502 | G27: =G24-G26 -> 22711 | H27: =H24-H26 -> 213 | I27: =I24-I26 -> 19673 | ... P27: =P24-P26 -> 15108.372
A29: PER SHARE DATA
A30: Weighted Avg. Shares Outstanding (Cr) | B30: 394.09 | C30: 382.86 | D30: 375.24 | E30: 375.24 | F30: 369.91 | G30: 365.91 | H30: 365.91 | I30: 361.81 | J30: 361.81 | K30: 361.81 | L30: =Assumptions!$C$37 -> 361.81 | M30: =Assumptions!$C$37 -> 361.81 | N30: =Assumptions!$C$37 -> 361.81 | O30: =Assumptions!$C$37 -> 361.81 | P30: =Assumptions!$C$37 -> 361.81
A31: Earnings Per Share — Basic (₹) | B31: =B24/B30 -> 66.878124 | C31: =C24/C30 -> 67.59651 | D31: =D24/D30 -> 84.111502 | E31: =E24/E30 -> 86.469993 | F31: =F24/F30 -> 88.026817 | G31: =G24/G30 -> 105.07775 | H31: =H24/H30 -> 115.6104 | I31: =I24/I30 -> 127.41218 | ... P31: =P24/P30 -> 208.78875
A32: Dividend Per Share (₹) | B32: =B26/B30 -> 23.494633 | C32: =C26/C30 -> 24.943844 | D32: =D26/D30 -> 29.980812 | E32: =E26/E30 -> 72.95331 | F32: =F26/F30 -> 38.009245 | G32: =G26/G30 -> 43.010576 | H32: =H26/H30 -> 115.02829 | I32: =I26/I30 -> 73.038335 | ... P32: =P26/P30 -> 167.031

Sheet BS
A1: Balance Sheet
A2: Tata Consultancy Services Ltd. (Consolidated)
A4: ASSETS
A5: (₹ Crore, unless stated otherwise) | B5: FY2017 | C5: FY2018 | D5: FY2019 | E5: FY2020 | F5: FY2021 | G5: FY2022 | H5: FY2023 | I5: FY2024 | J5: FY2025 | K5: FY2026 | L5: FY2027E | M5: FY2028E | N5: FY2029E | O5: FY2030E | P5: FY2031E
A6: Net Block (Fixed Assets) | B6: 11701 | C6: 11973 | D6: 12290 | E6: 20928 | F6: 21021 | G6: 21298 | H6: 20515 | I6: 19604 | J6: 23053 | K6: 31343 | L6: =K6+Assumptions!L9*IS!L6-IS!L18 -> 37914.387 | M6: =L6+Assumptions!M9*IS!M6-IS!M18 -> 44978.628 | N6: =M6+Assumptions!N9*IS!N6-IS!N18 -> 50949.447 | O6: =N6+Assumptions!O9*IS!O6-IS!O18 -> 57397.932 | P6: =O6+Assumptions!P9*IS!P6-IS!P18 -> 64362.295
A7: Capital Work-in-Progress | B7: 1541 | C7: 1278 | D7: 963 | E7: 906 | F7: 926 | G7: 1205 | H7: 1234 | I7: 1564 | J7: 1546 | K7: 2665 | L7: =K7 -> 2665 | M7: =L7 -> 2665 | N7: =M7 -> 2665 | O7: =N7 -> 2665 | P7: =O7 -> 2665
A8: Investments | B8: 41980 | C8: 36008 | D8: 29330 | E8: 26356 | F8: 29373 | G8: 30485 | H8: 37163 | I8: 31762 | J8: 30964 | K8: 33988 | L8: =K8*(1+Assumptions!L6) -> 36367.16 | M8: =L8*(1+Assumptions!M6) -> 39094.697 | N8: =M8*(1+Assumptions!N6) -> 42222.273 | O8: =N8*(1+Assumptions!O6) -> 45600.055 | P8: =O8*(1+Assumptions!P6) -> 49248.059
A9: Trade Receivables | B9: 22617 | C9: 24943 | D9: 27346 | E9: 30532 | F9: 30079 | G9: 41810 | H9: 49954 | I9: 53577 | J9: 59046 | K9: 67714 | L9: =Assumptions!L11/365*IS!L6 -> 72015.198 | M9: =Assumptions!M11/365*IS!M6 -> 76574.856 | N9: =Assumptions!N11/365*IS!N6 -> 81792.044 | O9: =Assumptions!O11/365*IS!O6 -> 88335.407 | P9: =Assumptions!P11/365*IS!P6 -> 95402.24
A10: Inventory | B10: 21 | C10: 26 | D10: 10 | E10: 5 | F10: 8 | G10: 20 | H10: 28 | I10: 28 | J10: 21 | K10: 29 | L10: =K10 -> 29 | M10: =L10 -> 29 | N10: =M10 -> 29 | O10: =N10 -> 29 | P10: =O10 -> 29
A11: Cash & Bank Balances | B11: 4149 | C11: 7161 | D11: 12848 | E11: 9666 | F11: 9329 | G11: 18221 | H11: 11032 | I11: 13286 | J11: 15463 | K11: 12908 | L11: =CF!L30 -> 12255.47 | M11: =CF!M30 -> 12054.918 | N11: =CF!N30 -> 13179.768 | O11: =CF!O30 -> 13766.14 | P11: =CF!P30 -> 14405.223
A12: Other Assets, net (unbilled rev., prepaid, DTA, other) | B12: 20324 | C12: 23737 | D12: 31114 | E12: 31734 | F12: 39256 | G12: 27885 | H12: 22933 | I12: 25651 | J12: 28556 | K12: 32520 | L12: =Assumptions!L13*IS!L6 -> 34856.921 | M12: =Assumptions!M13*IS!M6 -> 37471.19 | N12: =Assumptions!N13*IS!N6 -> 40468.886 | O12: =Assumptions!O13*IS!O6 -> 43706.397 | P12: =Assumptions!P13*IS!P6 -> 47202.908
A13: Total Assets | B13: =SUM(B6:B12) -> 102333 | C13: =SUM(C6:C12) -> 105126 | D13: =SUM(D6:D12) -> 113901 | E13: =SUM(E6:E12) -> 120127 | F13: =SUM(F6:F12) -> 129992 | G13: =SUM(G6:G12) -> 140924 | H13: =SUM(H6:H12) -> 142859 | I13: =SUM(I6:I12) -> 145472 | ... P13: =SUM(P6:P12) -> 273314.73
A15: LIABILITIES & EQUITY
A16: Equity Share Capital | B16: 197 | C16: 191 | D16: 375 | E16: 375 | F16: 370 | G16: 366 | H16: 366 | I16: 362 | J16: 362 | K16: 362 | L16: =K16 -> 362 | M16: =L16 -> 362 | N16: =M16 -> 362 | O16: =N16 -> 362 | P16: =O16 -> 362
A17: Reserves & Surplus | B17: 86017 | C17: 84937 | D17: 89071 | E17: 83751 | F17: 86063 | G17: 88773 | H17: 90058 | I17: 90127 | J17: 94394 | K17: 106878 | L17: =K17+IS!L24-IS!L26 -> 117601.42 | M17: =L17+IS!M24-IS!M26 -> 129352.32 | N17: =M17+IS!N24-IS!N26 -> 142040.77 | O17: =N17+IS!O24-IS!O26 -> 156024.63 | P17: =O17+IS!P24-IS!P26 -> 171133
A18: Borrowings | B18: 289 | C18: 247 | D18: 62 | E18: 8174 | F18: 7795 | G18: 7818 | H18: 7688 | I18: 8021 | J18: 9392 | K18: 11283 | L18: =K18 -> 11283 | M18: =L18 -> 11283 | N18: =M18 -> 11283 | O18: =N18 -> 11283 | P18: =O18 -> 11283
A19: Other Liabilities & Provisions | B19: 15830 | C19: 19751 | D19: 24393 | E19: 27827 | F19: 35764 | G19: 43967 | H19: 44747 | I19: 46962 | J19: 54501 | K19: 62644 | L19: =Assumptions!L12*IS!L6 -> 66856.718 | M19: =Assumptions!M12*IS!M6 -> 71870.972 | N19: =Assumptions!N12*IS!N6 -> 77620.65 | O19: =Assumptions!O12*IS!O6 -> 83830.302 | P19: =Assumptions!P12*IS!P6 -> 90536.726
A20: Total Liabilities & Equity | B20: =SUM(B16:B19) -> 102333 | C20: =SUM(C16:C19) -> 105126 | D20: =SUM(D16:D19) -> 113901 | E20: =SUM(E16:E19) -> 120127 | F20: =SUM(F16:F19) -> 129992 | G20: =SUM(G16:G19) -> 140924 | H20: =SUM(H16:H19) -> 142859 | I20: =SUM(I16:I19) -> 145472 | ... P20: =SUM(P16:P19) -> 273314.73
A22: Balance Check (Assets − Liab. & Equity) | B22: =B13-B20 -> 0 | C22: =C13-C20 -> 0 | D22: =D13-D20 -> 0 | E22: =E13-E20 -> 0 | F22: =F13-F20 -> 0 | G22: =G13-G20 -> 0 | H22: =H13-H20 -> 0 | I22: =I13-I20 -> 0 | ... P22: =P13-P20 -> 0
A24: WORKING CAPITAL & OTHER MEMO ITEMS
A25: Net Working Capital (Receiv. + Inv. − Other Liab.) | B25: =B9+B10-B19 -> 6808 | C25: =C9+C10-C19 -> 5218 | D25: =D9+D10-D19 -> 2963 | E25: =E9+E10-E19 -> 2710 | F25: =F9+F10-F19 -> -5677 | G25: =G9+G10-G19 -> -2137 | H25: =H9+H10-H19 -> 5235 | I25: =I9+I10-I19 -> 6643 | ... P25: =P9+P10-P19 -> 4894.5142
A26: Net Debt / (Net Cash) | B26: =B18-B11-B8 -> -45840 | C26: =C18-C11-C8 -> -42922 | D26: =D18-D11-D8 -> -42116 | E26: =E18-E11-E8 -> -27848 | F26: =F18-F11-F8 -> -30907 | G26: =G18-G11-G8 -> -40888 | H26: =H18-H11-H8 -> -40507 | I26: =I18-I11-I8 -> -37027 | ... P26: =P18-P11-P8 -> -52370.282
A27: Book Value Per Share (₹) | B27: =(B16+B17)/IS!B30 -> 218.76729 | C27: =(C16+C17)/IS!C30 -> 222.34759 | D27: =(D16+D17)/IS!D30 -> 238.37011 | E27: =(E16+E17)/IS!E30 -> 224.19252 | F27: =(F16+F17)/IS!F30 -> 233.65954 | G27: =(G16+G17)/IS!G30 -> 243.60908 | H27: =(H16+H17)/IS!H30 -> 247.12088 | I27: =(I16+I17)/IS!I30 -> 250.10088 | ... P27: =(P16+P17)/IS!P30 -> 473.99187

Sheet CF
A1: Cash Flow Statement
A2: Tata Consultancy Services Ltd. (Consolidated)
A4: A. CASH FLOW — AS REPORTED (HISTORICAL ACTUALS)
A5: (₹ Crore, unless stated otherwise) | B5: FY2017 | C5: FY2018 | D5: FY2019 | E5: FY2020 | F5: FY2021 | G5: FY2022 | H5: FY2023 | I5: FY2024 | J5: FY2025 | K5: FY2026 | L5: FY2027E | M5: FY2028E | N5: FY2029E | O5: FY2030E | P5: FY2031E
A6: Cash Flow from Operating Activities | B6: 25223 | C6: 25067 | D6: 28593 | E6: 32369 | F6: 38802 | G6: 39949 | H6: 41965 | I6: 44338 | J6: 48908 | K6: 52094 | L6: — | M6: — | N6: — | O6: — | P6: —
A7: Cash Flow from Investing Activities | B7: -16895 | C7: 3104 | D7: 1645 | E7: 8968 | F7: -7956 | G7: -738 | H7: 548 | I7: 6091 | J7: -2144 | K7: -11886 | L7: — | M7: — | N7: — | O7: — | P7: —
A8: Cash Flow from Financing Activities | B8: -11026 | C8: -26885 | D8: -27897 | E8: -39915 | F8: -32634 | G8: -33581 | H8: -47878 | I8: -48536 | J8: -47438 | K8: -42133 | L8: — | M8: — | N8: — | O8: — | P8: —
A9: Net Increase / (Decrease) in Cash | B9: =SUM(B6:B8) -> -2698 | C9: =SUM(C6:C8) -> 1286 | D9: =SUM(D6:D8) -> 2341 | E9: =SUM(E6:E8) -> 1422 | F9: =SUM(F6:F8) -> -1788 | G9: =SUM(G6:G8) -> 5630 | H9: =SUM(H6:H8) -> -5365 | I9: =SUM(I6:I8) -> 1893 | ... K9: =SUM(K6:K8) -> -1925 | L9: — | M9: — | N9: — | O9: — | P9: —
A10: Opening Cash Balance | B10: n/a | C10: =BS!B11 -> 4149 | D10: =BS!C11 -> 7161 | E10: =BS!D11 -> 12848 | F10: =BS!E11 -> 9666 | G10: =BS!F11 -> 9329 | H10: =BS!G11 -> 18221 | I10: =BS!H11 -> 11032 | J10: =BS!I11 -> 13286 | K10: =BS!J11 -> 15463 | L10: — | M10: — | N10: — | O10: — | P10: —
A11: Closing Cash Balance (check vs. Balance Sheet) | B11: n/a | C11: =C10+C9-BS!C11 -> -1726 | D11: =D10+D9-BS!D11 -> -3346 | E11: =E10+E9-BS!E11 -> 4604 | F11: =F10+F9-BS!F11 -> -1451 | G11: =G10+G9-BS!G11 -> -3262 | H11: =H10+H9-BS!H11 -> 1824 | I11: =I10+I9-BS!I11 -> -361 | J11: =J10+J9-BS!J11 -> -2851 | K11: =K10+K9-BS!K11 -> 630 | L11: — | M11: — | N11: — | O11: — | P11: —
A13: B. CASH FLOW — PROJECTED / MODEL-DERIVED (INDIRECT METHOD, ALL PERIODS)
A14: (₹ Crore, unless stated otherwise) | B14: FY2017 | C14: FY2018 | D14: FY2019 | E14: FY2020 | F14: FY2021 | G14: FY2022 | H14: FY2023 | I14: FY2024 | J14: FY2025 | K14: FY2026 | L14: FY2027E | M14: FY2028E | N14: FY2029E | O14: FY2030E | P14: FY2031E
A15: Net Profit After Tax | B15: =IS!B24 -> 26356 | C15: =IS!C24 -> 25880 | D15: =IS!D24 -> 31562 | E15: =IS!E24 -> 32447 | F15: =IS!F24 -> 32562 | G15: =IS!G24 -> 38449 | H15: =IS!H24 -> 42303 | I15: =IS!I24 -> 46099 | ... P15: =IS!P24 -> 75541.858
A16: Add: Depreciation & Amortization | B16: =IS!B18 -> 1987 | C16: =IS!C18 -> 2014 | D16: =IS!D18 -> 2056 | E16: =IS!E18 -> 3529 | F16: =IS!F18 -> 4065 | G16: =IS!G18 -> 4604 | H16: =IS!H18 -> 5022 | I16: =IS!I18 -> 4985 | ... P16: =IS!P18 -> 8511.9998
A17: Less: (Incr.)/Decr. in Receivables | B17: n/a | C17: =-(BS!C9-BS!B9) -> -2326 | D17: =-(BS!D9-BS!C9) -> -2403 | E17: =-(BS!E9-BS!D9) -> -3186 | F17: =-(BS!F9-BS!E9) -> 453 | G17: =-(BS!G9-BS!F9) -> -11731 | H17: =-(BS!H9-BS!G9) -> -8144 | I17: =-(BS!I9-BS!H9) -> -3623 | J17: =-(BS!J9-BS!I9) -> -5469 | ... P17: =-(BS!P9-BS!O9) -> -7066.8326
A18: Less: (Incr.)/Decr. in Inventory | B18: n/a | C18: =-(BS!C10-BS!B10) -> -5 | D18: =-(BS!D10-BS!C10) -> 16 | E18: =-(BS!E10-BS!D10) -> 5 | F18: =-(BS!F10-BS!E10) -> -3 | G18: =-(BS!G10-BS!F10) -> -12 | H18: =-(BS!H10-BS!G10) -> -8 | I18: =-(BS!I10-BS!H10) -> 0 | J18: =-(BS!J10-BS!I10) -> 7 | ... P18: =-(BS!P10-BS!O10) -> 0
A19: Less: (Incr.)/Decr. in Other Assets | B19: n/a | C19: =-(BS!C12-BS!B12) -> -3413 | D19: =-(BS!D12-BS!C12) -> -7377 | E19: =-(BS!E12-BS!D12) -> -620 | F19: =-(BS!F12-BS!E12) -> -7522 | G19: =-(BS!G12-BS!F12) -> 11371 | H19: =-(BS!H12-BS!G12) -> 4952 | I19: =-(BS!I12-BS!H12) -> -2718 | J19: =-(BS!J12-BS!I12) -> -2905 | ... P19: =-(BS!P12-BS!O12) -> -3496.5117
A20: Add: Incr./(Decr.) in Other Liabilities | B20: n/a | C20: =(BS!C19-BS!B19) -> 3921 | D20: =(BS!D19-BS!C19) -> 4642 | E20: =(BS!E19-BS!D19) -> 3434 | F20: =(BS!F19-BS!E19) -> 7937 | G20: =(BS!G19-BS!F19) -> 8203 | H20: =(BS!H19-BS!G19) -> 780 | I20: =(BS!I19-BS!H19) -> 2215 | J20: =(BS!J19-BS!I19) -> 7539 | ... P20: =(BS!P19-BS!O19) -> 6706.4241
A21: Cash Flow from Operating Activities (derived) | B21: n/a | C21: =SUM(C15:C20) -> 26071 | D21: =SUM(D15:D20) -> 28496 | E21: =SUM(E15:E20) -> 35609 | F21: =SUM(F15:F20) -> 37492 | G21: =SUM(G15:G20) -> 50884 | H21: =SUM(H15:H20) -> 44905 | I21: =SUM(I15:I20) -> 46958 | J21: =SUM(J15:J20) -> 53211 | ... P21: =SUM(P15:P20) -> 80196.938
A22: Less: Capital Expenditure | B22: n/a | C22: =-((BS!C6+BS!C7)-(BS!B6+BS!B7)+IS!C18) -> -2023 | D22: =-((BS!D6+BS!D7)-(BS!C6+BS!C7)+IS!D18) -> -2058 | E22: =-((BS!E6+BS!E7)-(BS!D6+BS!D7)+IS!E18) -> -12110 | F22: =-((BS!F6+BS!F7)-(BS!E6+BS!E7)+IS!F18) -> -4178 | G22: =-((BS!G6+BS!G7)-(BS!F6+BS!F7)+IS!G18) -> -5160 | H22: =-((BS!H6+BS!H7)-(BS!G6+BS!G7)+IS!H18) -> -4268 | I22: =-((BS!I6+BS!I7)-(BS!H6+BS!H7)+IS!I18) -> -4404 | J22: =-((BS!J6+BS!J7)-(BS!I6+BS!I7)+IS!J18) -> -8673 | ... P22: =-((BS!P6+BS!P7)-(BS!O6+BS!O7)+IS!P18) -> -15476.363
A23: Less: Incr. in Investments | B23: n/a | C23: =-(BS!C8-BS!B8) -> 5972 | D23: =-(BS!D8-BS!C8) -> 6678 | E23: =-(BS!E8-BS!D8) -> 2974 | F23: =-(BS!F8-BS!E8) -> -3017 | G23: =-(BS!G8-BS!F8) -> -1112 | H23: =-(BS!H8-BS!G8) -> -6678 | I23: =-(BS!I8-BS!H8) -> 5401 | J23: =-(BS!J8-BS!I8) -> 798 | ... P23: =-(BS!P8-BS!O8) -> -3648.0044
A24: Cash Flow from Investing Activities (derived) | B24: n/a | C24: =SUM(C22:C23) -> 3949 | D24: =SUM(D22:D23) -> 4620 | E24: =SUM(E22:E23) -> -9136 | F24: =SUM(F22:F23) -> -7195 | G24: =SUM(G22:G23) -> -6272 | H24: =SUM(H22:H23) -> -10946 | I24: =SUM(I22:I23) -> 997 | J24: =SUM(J22:J23) -> -7875 | ... P24: =SUM(P22:P23) -> -19124.368
A25: Add: Incr./(Decr.) in Borrowings | B25: n/a | C25: =(BS!C18-BS!B18) -> -42 | D25: =(BS!D18-BS!C18) -> -185 | E25: =(BS!E18-BS!D18) -> 8112 | F25: =(BS!F18-BS!E18) -> -379 | G25: =(BS!G18-BS!F18) -> 23 | H25: =(BS!H18-BS!G18) -> -130 | I25: =(BS!I18-BS!H18) -> 333 | J25: =(BS!J18-BS!I18) -> 1371 | ... P25: =(BS!P18-BS!O18) -> 0
A26: Less: Dividends Paid | B26: =-IS!B26 -> -9259 | C26: =-IS!C26 -> -9550 | D26: =-IS!D26 -> -11250 | E26: =-IS!E26 -> -27375 | F26: =-IS!F26 -> -14060 | G26: =-IS!G26 -> -15738 | H26: =-IS!H26 -> -42090 | I26: =-IS!I26 -> -26426 | ... P26: =-IS!P26 -> -60433.486
A27: Cash Flow from Financing Activities (derived) | B27: n/a | C27: =SUM(C25:C26) -> -9592 | D27: =SUM(D25:D26) -> -11435 | E27: =SUM(E25:E26) -> -19263 | F27: =SUM(F25:F26) -> -14439 | G27: =SUM(G25:G26) -> -15715 | H27: =SUM(H25:H26) -> -42220 | I27: =SUM(I25:I26) -> -26093 | J27: =SUM(J25:J26) -> -44241 | ... P27: =SUM(P25:P26) -> -60433.486
A28: Net Increase / (Decrease) in Cash (derived) | B28: n/a | C28: =C21+C24+C27 -> 20428 | D28: =D21+D24+D27 -> 21681 | E28: =E21+E24+E27 -> 7210 | F28: =F21+F24+F27 -> 15858 | G28: =G21+G24+G27 -> 28897 | H28: =H21+H24+H27 -> -8261 | I28: =I21+I24+I27 -> 21862 | J28: =J21+J24+J27 -> 1095 | ... P28: =P21+P24+P27 -> 639.08353
A29: Opening Cash Balance | B29: n/a | C29: =BS!B11 -> 4149 | D29: =BS!C11 -> 7161 | E29: =BS!D11 -> 12848 | F29: =BS!E11 -> 9666 | G29: =BS!F11 -> 9329 | H29: =BS!G11 -> 18221 | I29: =BS!H11 -> 11032 | J29: =BS!I11 -> 13286 | ... L29: =BS!K11 -> 12908 | M29: =L30 -> 12255.47 | N29: =M30 -> 12054.918 | O29: =N30 -> 13179.768 | P29: =O30 -> 13766.14
A30: Closing Cash Balance (derived) | B30: n/a | C30: =C29+C28 -> 24577 | D30: =D29+D28 -> 28842 | E30: =E29+E28 -> 20058 | F30: =F29+F28 -> 25524 | G30: =G29+G28 -> 38226 | H30: =H29+H28 -> 9960 | I30: =I29+I28 -> 32894 | J30: =J29+J28 -> 14381 | ... P30: =P29+P28 -> 14405.223
A32: Free Cash Flow to Firm (memo) — see DCF sheet for full build

Sheet Ratios
A1: Ratio Analysis
A2: Tata Consultancy Services Ltd. — Historical & Projected
A4: GROWTH
A5: (₹ Crore, unless stated otherwise) | B5: FY2017 | C5: FY2018 | D5: FY2019 | E5: FY2020 | F5: FY2021 | G5: FY2022 | H5: FY2023 | I5: FY2024 | J5: FY2025 | K5: FY2026 | L5: FY2027E | M5: FY2028E | N5: FY2029E | O5: FY2030E | P5: FY2031E
A6: Revenue Growth % YoY | C6: =IS!C7 -> 0.043554923 | D6: =IS!D7 -> 0.18975013 | E6: =IS!E7 -> 0.071594874 | F6: =IS!F7 -> 0.046053177 | G6: =IS!G7 -> 0.16797115 | H6: =IS!H7 -> 0.17576687 | I6: =IS!I7 -> 0.068460645 | J6: =IS!J7 -> 0.059906265 | ... P6: =IS!P7 -> 0.08
A7: EBITDA Growth % YoY | C7: =IFERROR(IS!C15/IS!B15-1,"") -> 0.0063757351 | D7: =IFERROR(IS!D15/IS!C15-1,"") -> 0.21497109 | E7: =IFERROR(IS!E15/IS!D15-1,"") -> 0.065888726 | F7: =IFERROR(IS!F15/IS!E15-1,"") -> 0.1053694 | G7: =IFERROR(IS!G15/IS!F15-1,"") -> 0.13988313 | H7: =IFERROR(IS!H15/IS!G15-1,"") -> 0.11689315 | I7: =IFERROR(IS!I15/IS!H15-1,"") -> 0.084999747 | J7: =IFERROR(IS!J15/IS!I15-1,"") -> 0.048385592 | ... P7: =IFERROR(IS!P15/IS!O15-1,"") -> 0.08
A8: Net Profit Growth % YoY | C8: =IFERROR(IS!C24/IS!B24-1,"") -> -0.018060404 | D8: =IFERROR(IS!D24/IS!C24-1,"") -> 0.21955178 | E8: =IFERROR(IS!E24/IS!D24-1,"") -> 0.028040048 | F8: =IFERROR(IS!F24/IS!E24-1,"") -> 0.0035442414 | G8: =IFERROR(IS!G24/IS!F24-1,"") -> 0.18079356 | H8: =IFERROR(IS!H24/IS!G24-1,"") -> 0.10023668 | I8: =IFERROR(IS!I24/IS!H24-1,"") -> 0.089733589 | J8: =IFERROR(IS!J24/IS!I24-1,"") -> 0.058526215 | ... P8: =IFERROR(IS!P24/IS!O24-1,"") -> 0.080414922
A9: EPS Growth % YoY | C9: =IFERROR(IS!C31/IS!B31-1,"") -> 0.010741722 | D9: =IFERROR(IS!D31/IS!C31-1,"") -> 0.24431722 | E9: =IFERROR(IS!E31/IS!D31-1,"") -> 0.028040048 | F9: =IFERROR(IS!F31/IS!E31-1,"") -> 0.01800422 | G9: =IFERROR(IS!G31/IS!F31-1,"") -> 0.19370158 | H9: =IFERROR(IS!H31/IS!G31-1,"") -> 0.10023668 | I9: =IFERROR(IS!I31/IS!H31-1,"") -> 0.10208236 | J9: =IFERROR(IS!J31/IS!I31-1,"") -> 0.058526215 | ... P9: =IFERROR(IS!P31/IS!O31-1,"") -> 0.080414922
A11: PROFITABILITY
A12: EBITDA Margin % | B12: =IS!B16 -> 0.27389248 | C12: =IS!C16 -> 0.26413439 | D12: =IS!D16 -> 0.26973365 | E12: =IS!E16 -> 0.26829734 | F12: =IS!F16 -> 0.28351109 | G12: =IS!G16 -> 0.27669305 | H12: =IS!H16 -> 0.26283831 | I12: =IS!I16 -> 0.26690688 | ... P12: =IS!P16 -> 0.275
A13: EBIT Margin % | B13: =IS!B19/IS!B6 -> 0.25704864 | C13: =IS!C19/IS!C6 -> 0.24777424 | D13: =IS!D19/IS!D6 -> 0.25569598 | E13: =IS!E19/IS!E6 -> 0.24581233 | F13: =IS!F19/IS!F6 -> 0.25875123 | G13: =IS!G19/IS!G6 -> 0.25268313 | H13: =IS!H19/IS!H6 -> 0.24056365 | I13: =IS!I19/IS!I6 -> 0.24621305 | ... P13: =IS!P19/IS!P6 -> 0.253
A14: Net Profit Margin % | B14: =IS!B25 -> 0.22342031 | C14: =IS!C25 -> 0.21022875 | D14: =IS!D25 -> 0.2154947 | E14: =IS!E25 -> 0.20673595 | F14: =IS!F25 -> 0.19833472 | G14: =IS!G25 -> 0.20051211 | H14: =IS!H25 -> 0.1876314 | I14: =IS!I25 -> 0.19136712 | ... P14: =IS!P25 -> 0.19524447
A15: Return on Equity (ROE) % | B15: =IS!B24/(BS!B16+BS!B17) -> 0.30570441 | C15: =IFERROR(IS!C24/AVERAGE(BS!B16+BS!B17,BS!C16+BS!C17),"") -> 0.30208589 | D15: =IFERROR(IS!D24/AVERAGE(BS!C16+BS!C17,BS!D16+BS!D17),"") -> 0.36158878 | E15: =IFERROR(IS!E24/AVERAGE(BS!D16+BS!D17,BS!E16+BS!E17),"") -> 0.37387367 | F15: =IFERROR(IS!F24/AVERAGE(BS!E16+BS!E17,BS!F16+BS!F17),"") -> 0.38182682 | G15: =IFERROR(IS!G24/AVERAGE(BS!F16+BS!F17,BS!G16+BS!G17),"") -> 0.43798556 | H15: =IFERROR(IS!H24/AVERAGE(BS!G16+BS!G17,BS!H16+BS!H17),"") -> 0.47117725 | I15: =IFERROR(IS!I24/AVERAGE(BS!H16+BS!H17,BS!I16+BS!I17),"") -> 0.50962617 | J15: =IFERROR(IS!J24/AVERAGE(BS!I16+BS!I17,BS!J16+BS!J17),"") -> 0.52683743 | ... P15: =IFERROR(IS!P24/AVERAGE(BS!O16+BS!O17,BS!P16+BS!P17),"") -> 0.46078738
A16: Return on Capital Employed (ROCE) % | B16: =IS!B19/(BS!B16+BS!B17+BS!B18) -> 0.35054276 | C16: =IFERROR(IS!C19/AVERAGE(BS!B16+BS!B17+BS!B18,BS!C16+BS!C17+BS!C18),"") -> 0.35492617 | D16: =IFERROR(IS!D19/AVERAGE(BS!C16+BS!C17+BS!C18,BS!D16+BS!D17+BS!D18),"") -> 0.42828634 | E16: =IFERROR(IS!E19/AVERAGE(BS!D16+BS!D17+BS!D18,BS!E16+BS!E17+BS!E18),"") -> 0.42440377 | F16: =IFERROR(IS!F19/AVERAGE(BS!E16+BS!E17+BS!E18,BS!F16+BS!F17+BS!F18),"") -> 0.45549194 | G16: =IFERROR(IS!G19/AVERAGE(BS!F16+BS!F17+BS!F18,BS!G16+BS!G17+BS!G18),"") -> 0.50687031 | H16: =IFERROR(IS!H19/AVERAGE(BS!G16+BS!G17+BS!G18,BS!H16+BS!H17+BS!H18),"") -> 0.55608016 | I16: =IFERROR(IS!I19/AVERAGE(BS!H16+BS!H17+BS!H18,BS!I16+BS!I17+BS!I18),"") -> 0.60329973 | J16: =IFERROR(IS!J19/AVERAGE(BS!I16+BS!I17+BS!I18,BS!J16+BS!J17+BS!J18),"") -> 0.61349663 | ... P16: =IFERROR(IS!P19/AVERAGE(BS!O16+BS!O17+BS!O18,BS!P16+BS!P17+BS!P18),"") -> 0.55864552
A17: Return on Assets (ROA) % | B17: =IS!B24/BS!B13 -> 0.25755133 | C17: =IFERROR(IS!C24/AVERAGE(BS!B13,BS!C13),"") -> 0.24949508 | D17: =IFERROR(IS!D24/AVERAGE(BS!C13,BS!D13),"") -> 0.28820191 | E17: =IFERROR(IS!E24/AVERAGE(BS!D13,BS!E13),"") -> 0.27729161 | F17: =IFERROR(IS!F24/AVERAGE(BS!E13,BS!F13),"") -> 0.26037206 | G17: =IFERROR(IS!G24/AVERAGE(BS!F13,BS!G13),"") -> 0.28384444 | H17: =IFERROR(IS!H24/AVERAGE(BS!G13,BS!H13),"") -> 0.29813625 | I17: =IFERROR(IS!I24/AVERAGE(BS!H13,BS!I13),"") -> 0.31976444 | J17: =IFERROR(IS!J24/AVERAGE(BS!I13,BS!J13),"") -> 0.32090517 | ... P17: =IFERROR(IS!P24/AVERAGE(BS!O13,BS!P13),"") -> 0.28788014
A19: EFFICIENCY
A20: Receivable Days (DSO) | B20: =BS!B9/IS!B6*365 -> 69.979528 | C20: =BS!C9/IS!C6*365 -> 73.955314 | D20: =BS!D9/IS!D6*365 -> 68.148884 | E20: =BS!E9/IS!E6*365 -> 71.005104 | F20: =BS!F9/IS!F6*365 -> 66.871943 | G20: =BS!G9/IS!G6*365 -> 79.58452 | H20: =BS!H9/IS!H6*365 -> 80.87187 | I20: =BS!I9/IS!I6*365 -> 81.179632 | ... P20: =BS!P9/IS!P6*365 -> 90
A21: Asset Turnover (x) | B21: =IS!B6/BS!B13 -> 1.152766 | C21: =IS!C6/BS!C13 -> 1.1710138 | D21: =IS!D6/BS!D13 -> 1.2858798 | E21: =IS!E6/BS!E13 -> 1.3065256 | F21: =IS!F6/BS!F13 -> 1.2629777 | G21: =IS!G6/BS!G13 -> 1.3606909 | H21: =IS!H6/BS!H13 -> 1.5781855 | I21: =IS!I6/BS!I13 -> 1.6559407 | ... P21: =IS!P6/BS!P13 -> 1.4156174
A22: Fixed Asset Turnover (x) | B22: =IS!B6/(BS!B6+BS!B7) -> 8.908473 | C22: =IS!C6/(BS!C6+BS!C7) -> 9.2901668 | D22: =IS!D6/(BS!D6+BS!D7) -> 11.051309 | E22: =IS!E6/(BS!E6+BS!E7) -> 7.1882843 | F22: =IS!F6/(BS!F6+BS!F7) -> 7.4806124 | G22: =IS!G6/(BS!G6+BS!G7) -> 8.5212638 | H22: =IS!H6/(BS!H6+BS!H7) -> 10.366362 | I22: =IS!I6/(BS!I6+BS!I7) -> 11.380055 | ... P22: =IS!P6/(BS!P6+BS!P7) -> 5.7724108
A24: LEVERAGE & COVERAGE
A25: Debt / Equity (x) | B25: =BS!B18/(BS!B16+BS!B17) -> 0.0033521238 | C25: =BS!C18/(BS!C16+BS!C17) -> 0.002901513 | D25: =BS!D18/(BS!D16+BS!D17) -> 0.00069315565 | E25: =BS!E18/(BS!E16+BS!E17) -> 0.097163778 | F25: =BS!F18/(BS!F16+BS!F17) -> 0.090185462 | G25: =BS!G18/(BS!G16+BS!G17) -> 0.087705718 | H25: =BS!H18/(BS!H16+BS!H17) -> 0.085021676 | I25: =BS!I18/(BS!I16+BS!I17) -> 0.088640608 | ... P25: =BS!P18/(BS!P16+BS!P17) -> 0.065792006
A26: Debt / EBITDA (x) | B26: =BS!B18/IS!B15 -> 0.0089445992 | C26: =BS!C18/IS!C15 -> 0.0075962603 | D26: =BS!D18/IS!D15 -> 0.0015693819 | E26: =BS!E18/IS!E15 -> 0.19411527 | F26: =BS!F18/IS!F15 -> 0.16746874 | G26: =BS!G18/IS!G15 -> 0.14735096 | H26: =BS!H18/IS!H15 -> 0.12973557 | I26: =BS!I18/IS!I15 -> 0.12475115 | ... P26: =BS!P18/IS!P15 -> 0.10604323
A27: Interest Coverage Ratio (x) | B27: =IFERROR(IS!B19/IS!B20,"") -> 947.59375 | C27: =IFERROR(IS!C19/IS!C20,"") -> 586.57692 | D27: =IFERROR(IS!D19/IS!D20,"") -> 189.14141 | E27: =IFERROR(IS!E19/IS!E20,"") -> 41.753247 | F27: =IFERROR(IS!F19/IS!F20,"") -> 66.689168 | G27: =IFERROR(IS!G19/IS!G20,"") -> 61.802296 | H27: =IFERROR(IS!H19/IS!H20,"") -> 69.623877 | I27: =IFERROR(IS!I19/IS!I20,"") -> 76.235219 | ... P27: =IFERROR(IS!P19/IS!P20,"") -> 115.67609
A28: Net Debt / EBITDA (x) | B28: =BS!B26/IS!B15 -> -1.4187558 | C28: =BS!C26/IS!C15 -> -1.3200271 | D28: =BS!D26/IS!D15 -> -1.0660659 | E28: =BS!E26/IS!E15 -> -0.66133131 | F28: =BS!F26/IS!F15 -> -0.6640098 | G28: =BS!G26/IS!G15 -> -0.77064289 | H28: =BS!H26/IS!H15 -> -0.68355862 | I28: =BS!I26/IS!I15 -> -0.57588341 | ... P28: =BS!P26/IS!P15 -> -0.49220191
A30: PER SHARE & VALUATION
A31: Market Price per Share (₹) | B31: 1215.9 | C31: 1424.58 | D31: 2001.65 | E31: 1826.1 | F31: 3177.85 | G31: 3739.95 | H31: 3205.9 | I31: 3876.3 | J31: 3606.15 | K31: 2358.9 | L31: =Assumptions!$C$35 -> 2093.5 | M31: =Assumptions!$C$35 -> 2093.5 | N31: =Assumptions!$C$35 -> 2093.5 | O31: =Assumptions!$C$35 -> 2093.5 | P31: =Assumptions!$C$35 -> 2093.5
A32: Earnings Per Share (₹) | B32: =IS!B31 -> 66.878124 | C32: =IS!C31 -> 67.59651 | D32: =IS!D31 -> 84.111502 | E32: =IS!E31 -> 86.469993 | F32: =IS!F31 -> 88.026817 | G32: =IS!G31 -> 105.07775 | H32: =IS!H31 -> 115.6104 | I32: =IS!I31 -> 127.41218 | ... P32: =IS!P31 -> 208.78875
A33: P/E Ratio (x) | B33: =B31/B32 -> 18.180833 | C33: =C31/C32 -> 21.074757 | D33: =D31/D32 -> 23.797578 | E33: =E31/E32 -> 21.118309 | F33: =F31/F32 -> 36.10093 | G33: =G31/G32 -> 35.592216 | H33: =H31/H32 -> 27.730205 | I33: =I31/I32 -> 30.423309 | ... P33: =P31/P32 -> 10.026881
A34: Book Value per Share (₹) | B34: =BS!B27 -> 218.76729 | C34: =BS!C27 -> 222.34759 | D34: =BS!D27 -> 238.37011 | E34: =BS!E27 -> 224.19252 | F34: =BS!F27 -> 233.65954 | G34: =BS!G27 -> 243.60908 | H34: =BS!H27 -> 247.12088 | I34: =BS!I27 -> 250.10088 | ... P34: =BS!P27 -> 473.99187
A35: P/B Ratio (x) | B35: =B31/B34 -> 5.5579608 | C35: =C31/C34 -> 6.4069953 | D35: =D31/D34 -> 8.3972357 | E35: =E31/E34 -> 8.1452317 | F35: =F31/F34 -> 13.600344 | G35: =G31/G34 -> 15.35226 | H35: =H31/H34 -> 12.973004 | I35: =I31/I34 -> 15.498946 | ... P35: =P31/P34 -> 4.4167424
A36: Dividend per Share (₹) | B36: =IS!B32 -> 23.494633 | C36: =IS!C32 -> 24.943844 | D36: =IS!D32 -> 29.980812 | E36: =IS!E32 -> 72.95331 | F36: =IS!F32 -> 38.009245 | G36: =IS!G32 -> 43.010576 | H36: =IS!H32 -> 115.02829 | I36: =IS!I32 -> 73.038335 | ... P36: =IS!P32 -> 167.031
A37: Dividend Yield % | B37: =B36/B31 -> 0.019322833 | C37: =C36/C31 -> 0.017509612 | D37: =D36/D31 -> 0.014978049 | E37: =E36/E31 -> 0.039950337 | F37: =F36/F31 -> 0.01196068 | G37: =G36/G31 -> 0.011500308 | H37: =H36/H31 -> 0.035880185 | I37: =I36/I31 -> 0.018842281 | ... P37: =P36/P31 -> 0.079785527
A38: EV / EBITDA (x) | B38: =(B31*IS!B30+BS!B18-BS!B11-BS!B8)/IS!B15 -> 13.411762 | C38: =(C31*IS!C30+BS!C18-BS!C11-BS!C8)/IS!C15 -> 15.453706 | D38: =(D31*IS!D30+BS!D18-BS!D11-BS!D8)/IS!D15 -> 17.946214 | E38: =(E31*IS!E30+BS!E18-BS!E11-BS!E8)/IS!E15 -> 15.611336 | F38: =(F31*IS!F30+BS!F18-BS!F11-BS!F8)/IS!F15 -> 24.590974 | G38: =(G31*IS!G30+BS!G18-BS!G11-BS!G8)/IS!G15 -> 25.022091 | H38: =(H31*IS!H30+BS!H18-BS!H11-BS!H8)/IS!H15 -> 19.112099 | I38: =(I31*IS!I30+BS!I18-BS!I11-BS!I8)/IS!I15 -> 21.237046 | ... P38: =(P31*IS!P30+BS!P18-BS!P11-BS!P8)/IS!P15 -> 6.626682

Sheet DCF
A1: DCF Valuation — Free Cash Flow to Firm (FCFF)
A2: Tata Consultancy Services Ltd.
A4: FREE CASH FLOW TO FIRM PROJECTION
A5: (₹ Crore, unless stated otherwise) | B5: FY2017 | C5: FY2018 | D5: FY2019 | E5: FY2020 | F5: FY2021 | G5: FY2022 | H5: FY2023 | I5: FY2024 | J5: FY2025 | K5: FY2026 | L5: FY2027E | M5: FY2028E | N5: FY2029E | O5: FY2030E | P5: FY2031E
A6: EBIT | B6: =IS!B19 -> 30323 | C6: =IS!C19 -> 30502 | D6: =IS!D19 -> 37450 | E6: =IS!E19 -> 38580 | F6: =IS!F19 -> 42481 | G6: =IS!G19 -> 48453 | H6: =IS!H19 -> 54237 | I6: =IS!I19 -> 59311 | ... P6: =IS!P19 -> 97887.998
A7: Less: Taxes on EBIT (at effective tax rate) | B7: =-B6*IS!B23 -> -7166.0404 | C7: =-C6*IS!C23 -> -7347.2493 | D7: =-D6*IS!D23 -> -9011.319 | E7: =-E6*IS!E23 -> -8950.0705 | F7: =-F6*IS!F23 -> -10870.709 | G7: =-G6*IS!G23 -> -12409.713 | H7: =-H6*IS!H23 -> -13918.8 | I7: =-I6*IS!I23 -> -15209.224 | ... P7: =-P6*IS!P23 -> -24472
A8: NOPAT (Tax-Effected EBIT) | B8: =B6+B7 -> 23156.96 | C8: =C6+C7 -> 23154.751 | D8: =D6+D7 -> 28438.681 | E8: =E6+E7 -> 29629.929 | F8: =F6+F7 -> 31610.291 | G8: =G6+G7 -> 36043.287 | H8: =H6+H7 -> 40318.2 | I8: =I6+I7 -> 44101.776 | ... P8: =P6+P7 -> 73415.999
A9: Add: Depreciation & Amortization | B9: =IS!B18 -> 1987 | C9: =IS!C18 -> 2014 | D9: =IS!D18 -> 2056 | E9: =IS!E18 -> 3529 | F9: =IS!F18 -> 4065 | G9: =IS!G18 -> 4604 | H9: =IS!H18 -> 5022 | I9: =IS!I18 -> 4985 | ... P9: =IS!P18 -> 8511.9998
A10: Less: Capital Expenditure | B10: n/a | C10: =CF!C22 -> -2023 | D10: =CF!D22 -> -2058 | E10: =CF!E22 -> -12110 | F10: =CF!F22 -> -4178 | G10: =CF!G22 -> -5160 | H10: =CF!H22 -> -4268 | I10: =CF!I22 -> -4404 | J10: =CF!J22 -> -8673 | ... P10: =CF!P22 -> -15476.363
A11: Less: Increase in Net Working Capital | B11: n/a | C11: =-(BS!C25-BS!B25) -> 1590 | D11: =-(BS!D25-BS!C25) -> 2255 | E11: =-(BS!E25-BS!D25) -> 253 | F11: =-(BS!F25-BS!E25) -> 8387 | G11: =-(BS!G25-BS!F25) -> -3540 | H11: =-(BS!H25-BS!G25) -> -7372 | I11: =-(BS!I25-BS!H25) -> -1408 | J11: =-(BS!J25-BS!I25) -> 2077 | ... P11: =-(BS!P25-BS!O25) -> -360.40846
A12: Free Cash Flow to Firm (FCFF) | B12: n/a | C12: =C8+C9+C10+C11 -> 24735.751 | D12: =D8+D9+D10+D11 -> 30691.681 | E12: =E8+E9+E10+E11 -> 21301.929 | F12: =F8+F9+F10+F11 -> 39884.291 | G12: =G8+G9+G10+G11 -> 31947.287 | H12: =H8+H9+H10+H11 -> 33700.2 | I12: =I8+I9+I10+I11 -> 43274.776 | J12: =J8+J9+J10+J11 -> 45078.253 | ... P12: =P8+P9+P10+P11 -> 66091.227
A14: DISCOUNTING — PROJECTION PERIOD (FY2027E–FY2031E)
A15: Discount period (n, years) | L15: 1 | M15: 2 | N15: 3 | O15: 4 | P15: 5
A16: FCFF (₹ Cr) | L16: =L12 -> 45411.231 | M16: =M12 -> 50518.563 | N16: =N12 -> 56260.136 | O16: =O12 -> 61195.58 | P16: =P12 -> 66091.227
A17: Discount Factor @ WACC | L17: =1/(1+Assumptions!$C$30)^L15 -> 0.88890316 | M17: =1/(1+Assumptions!$C$30)^M15 -> 0.79014882 | N17: =1/(1+Assumptions!$C$30)^N15 -> 0.70236578 | O17: =1/(1+Assumptions!$C$30)^O15 -> 0.62433516 | P17: =1/(1+Assumptions!$C$30)^P15 -> 0.55497349
A18: Present Value of FCFF | L18: =L16*L17 -> 40366.186 | M18: =M16*M17 -> 39917.183 | N18: =N16*N17 -> 39515.194 | O18: =O16*O17 -> 38206.552 | P18: =P16*P17 -> 36678.879
A20: TERMINAL VALUE (GORDON GROWTH)
A21: Terminal Year FCFF (FY2031E) | C21: =P16 -> 66091.227
A22: Terminal Growth Rate (g) | C22: =Assumptions!$C$32 -> 0.05
A23: WACC | C23: =Assumptions!$C$30 -> 0.12498194
A24: Terminal Value = FCFF₅×(1+g) / (WACC−g) | C24: =C21*(1+C22)/(C23-C22) -> 925499.98
A25: Discount Factor (Year 5) | C25: =P17 -> 0.55497349
A26: Present Value of Terminal Value | C26: =C24*C25 -> 513627.95
A28: ENTERPRISE VALUE → EQUITY VALUE BRIDGE
A29: Sum of PV of FCFF (FY27E–FY31E) | C29: =SUM(L18:P18) -> 194683.99
A30: Add: PV of Terminal Value | C30: =C26 -> 513627.95
A31: Enterprise Value | C31: =C29+C30 -> 708311.95
A32: Less: Total Debt (FY2026A) | C32: =-BS!K18 -> -11283
A33: Add: Cash & Bank (FY2026A) | C33: =BS!K11 -> 12908
A34: Add: Investments (FY2026A) | C34: =BS!K8 -> 33988
A35: Equity Value | C35: =C31+C32+C33+C34 -> 743924.95
A36: Shares Outstanding (Cr) | C36: =Assumptions!$C$37 -> 361.81
A37: Intrinsic Value per Share (₹) | C37: =C35/C36 -> 2056.1205
A38: Current Market Price (₹) | C38: =Assumptions!$C$35 -> 2093.5
A39: Upside / (Downside) % | C39: =C37/C38-1 -> -0.017855043
A41: SENSITIVITY ANALYSIS — INTRINSIC VALUE PER SHARE (₹)
A42: WACC (↓) \ Terminal Growth (→)
C43: =$C$22+-0.01 -> 0.04 | D43: =$C$22+-0.005 -> 0.045 | E43: =$C$22+0 -> 0.05 | F43: =$C$22+0.005 -> 0.055 | G43: =$C$22+0.01 -> 0.06
B44: =$C$23+-0.01 -> 0.11498194 | C44: =(SUMPRODUCT($L$16:$P$16,1/(1+$B44)^$L$15:$P$15)+($P$16*(1+C$43)/($B44-C$43))/(1+$B44)^$P$15+$C$32+$C$33+$C$34)/$C$36 -> 2121.2173 | D44: =(SUMPRODUCT($L$16:$P$16,1/(1+$B44)^$L$15:$P$15)+($P$16*(1+D$43)/($B44-D$43))/(1+$B44)^$P$15+$C$32+$C$33+$C$34)/$C$36 -> 2233.8383 | E44: =(SUMPRODUCT($L$16:$P$16,1/(1+$B44)^$L$15:$P$15)+($P$16*(1+E$43)/($B44-E$43))/(1+$B44)^$P$15+$C$32+$C$33+$C$34)/$C$36 -> 2363.7904 | F44: =(SUMPRODUCT($L$16:$P$16,1/(1+$B44)^$L$15:$P$15)+($P$16*(1+F$43)/($B44-F$43))/(1+$B44)^$P$15+$C$32+$C$33+$C$34)/$C$36 -> 2515.4076 | G44: =(SUMPRODUCT($L$16:$P$16,1/(1+$B44)^$L$15:$P$15)+($P$16*(1+G$43)/($B44-G$43))/(1+$B44)^$P$15+$C$32+$C$33+$C$34)/$C$36 -> 2694.6007
B45: =$C$23+-0.005 -> 0.11998194 | C45: =(SUMPRODUCT($L$16:$P$16,1/(1+$B45)^$L$15:$P$15)+($P$16*(1+C$43)/($B45-C$43))/(1+$B45)^$P$15+$C$32+$C$33+$C$34)/$C$36 -> 1991.5245 | D45: =(SUMPRODUCT($L$16:$P$16,1/(1+$B45)^$L$15:$P$15)+($P$16*(1+D$43)/($B45-D$43))/(1+$B45)^$P$15+$C$32+$C$33+$C$34)/$C$36 -> 2088.3167 | E45: =(SUMPRODUCT($L$16:$P$16,1/(1+$B45)^$L$15:$P$15)+($P$16*(1+E$43)/($B45-E$43))/(1+$B45)^$P$15+$C$32+$C$33+$C$34)/$C$36 -> 2198.94 | F45: =(SUMPRODUCT($L$16:$P$16,1/(1+$B45)^$L$15:$P$15)+($P$16*(1+F$43)/($B45-F$43))/(1+$B45)^$P$15+$C$32+$C$33+$C$34)/$C$36 -> 2326.587 | G45: =(SUMPRODUCT($L$16:$P$16,1/(1+$B45)^$L$15:$P$15)+($P$16*(1+G$43)/($B45-G$43))/(1+$B45)^$P$15+$C$32+$C$33+$C$34)/$C$36 -> 2475.5148
...

Sheet Comps
A1: Relative Valuation — Peer Comparison
A2: Trailing multiples, Indian IT Services large-caps
A4: PEER TRADING MULTIPLES (TRAILING)
A5: Company | B5: Mkt Cap (₹ Cr) | C5: P/E (x) | D5: EV/EBITDA (x) | E5: P/B (x) | F5: ROE %
A6: Tata Consultancy Services (TCS) | B6: =Assumptions!C36 -> 757449.23 | C6: =Ratios!K33 -> 17.257929 | D6: =Ratios!K38 -> 11.296729 | E6: =Ratios!K35 -> 7.9585379 | F6: =Ratios!K15 -> 0.48965326
A7: Infosys Ltd (INFY) | B7: 636000 | C7: 18.3 | D7: 12.1 | E7: 6 | F7: 0.327
A8: HCLTechnologies Ltd (HCLTECH) | B8: 442000 | C8: 22.5 | D8: 13.8 | E8: 5.4 | F8: 0.24
A9: Wipro Ltd (WIPRO) | B9: 258000 | C9: 21 | D9: 11.5 | E9: 3.3 | F9: 0.16
A10: Peer Average (excl. TCS) | B10: =AVERAGE(B7:B9) -> 445333.33 | C10: =AVERAGE(C7:C9) -> 20.6 | D10: =AVERAGE(D7:D9) -> 12.466667 | E10: =AVERAGE(E7:E9) -> 4.9 | F10: =AVERAGE(F7:F9) -> 0.24233333
A12: IMPLIED VALUATION — TCS AT PEER-AVERAGE MULTIPLES
A13: Basis | B13: Multiple (x) | C13: TCS Metric (FY26A, ₹ Cr) | D13: Implied Value
A14: P/E × FY2026A EPS | B14: =C10 -> 20.6 | C14: =IS!K31 -> 136.685 | D14: =B14*C14 -> 2815.711
A15: EV/EBITDA × FY2026A EBITDA (→ per share) | B15: =D10 -> 12.466667 | C15: =IS!K15 -> 72398 | D15: =(B15*C15-BS!K18+BS!K11+BS!K8)/Assumptions!$C$37 -> 2593.0039
A17: Current Market Price (₹) | D17: =Assumptions!$C$35 -> 2093.5
A18: DCF Intrinsic Value (₹) — see DCF sheet | D18: =DCF!C37 -> 2056.1205

Sheet Dashboard
A1: TCS — Valuation Dashboard
A2: Summary of Key Outputs
A4: VALUATION SUMMARY (₹ per share)
A5: Current Market Price | C5: =Assumptions!$C$35 -> 2093.5
A6: DCF Intrinsic Value (Base Case) | C6: =DCF!C37 -> 2056.1205
A7: Implied Value — Peer P/E | C7: =Comps!D14 -> 2815.711
A8: Implied Value — Peer EV/EBITDA | C8: =Comps!D15 -> 2593.0039
A9: DCF Upside / (Downside) vs. CMP | C9: =C6/C5-1 -> -0.017855043
A11: KEY OPERATING METRICS (FY2026A vs. FY2031E)
A12: Metric | B12: FY2026A | C12: FY2031E
A13: Revenue (₹ Cr) | B13: =IS!K6 -> 267021 | C13: =IS!P6 -> 386909.08
A14: EBITDA (₹ Cr) | B14: =IS!K15 -> 72398 | C14: =IS!P15 -> 106400
A15: EBITDA Margin % | B15: =IS!K16 -> 0.27113223 | C15: =IS!P16 -> 0.275
A16: Net Profit (₹ Cr) | B16: =IS!K24 -> 49454 | C16: =IS!P24 -> 75541.858
A17: EPS (₹) | B17: =IS!K31 -> 136.685 | C17: =IS!P31 -> 208.78875
A18: ROE % | B18: =Ratios!K15 -> 0.48965326 | C18: =Ratios!P15 -> 0.46078738
A19: Revenue CAGR FY2026A–FY2031E | C19: =(IS!P6/IS!K6)^(1/5)-1 -> 0.076992556
A21: REVENUE & EBITDA TREND (₹ CRORE)
A22: (chart below — historical FY2017 to projected FY2031E)
