Workbook

Sheet Cover
C3: SUN PHARMACEUTICAL INDUSTRIES LTD — INTEGRATED FINANCIAL MODEL & INTRINSIC VALUATION
C4: Integrated Financial Model & Intrinsic Valuation
C5: Three-Statement Model | DCF (FCFF) Valuation | Relative Valuation | Ratio Analysis
C8: Prepared for: Independent Equity Research / Illustrative Purposes
C9: Prepared: July 2026
C10: Currency: Indian Rupees (₹), figures in Crore (1 Cr = 10 million) unless stated otherwise
C11: Fiscal Year End: 31 March
C13: SNAPSHOT
C14: Current Market Price (₹) | E14: 1932.6
C15: Shares Outstanding (Cr) | E15: 239.93
C16: Market Capitalization (₹ Cr) | E16: 463688.72
C17: 52-Week Range / Sector | E17: ₹1548.00–₹1962.70 / Health Technology — Nifty Pharma
C19: CONTENTS
C20: 1. Assumptions & Cost of Capital
C21: 2. Income Statement
C22: 3. Balance Sheet
C23: 4. Cash Flow Statement
C24: 5. Ratio Analysis
C25: 6. DCF Valuation (FCFF)
C26: 7. Relative Valuation (Comps)
C27: 8. Dashboard & Football Field
C29: Color Legend: Blue = hardcoded input / historical actual figure. Black = formula / calculation. Green = link pulling from another worksheet. Disclaimer: This model is built from publicly available historical financial data and is intended for illustrative / educational purposes. Projections and assumptions (growth, margins, WACC inputs) are estimates and should be independently verified before use in an investment decision. This is not investment advice.

Sheet Assumptions
A1: SUN PHARMACEUTICAL INDUSTRIES LTD — Model Assumptions & Cost of Capital
A2: SUN PHARMACEUTICAL INDUSTRIES LTD (Consolidated)
A4: 1. OPERATING & WORKING CAPITAL ASSUMPTIONS (₹ Crore basis, ratios shown as %)
A5: (₹ Crore, unless stated otherwise) | B5: FY2017 | C5: FY2018 | D5: FY2019 | E5: FY2020 | F5: FY2021 | G5: FY2022 | H5: FY2023 | I5: FY2024 | J5: FY2025 | K5: FY2026 | L5: FY2027E | M5: FY2028E | N5: FY2029E | O5: FY2030E | P5: FY2031E
A6: Revenue growth % (YoY) | C6: =IFERROR(IS!C6/IS!B6-1,"") | D6: =IFERROR(IS!D6/IS!C6-1,"") | E6: =IFERROR(IS!E6/IS!D6-1,"") | F6: =IFERROR(IS!F6/IS!E6-1,"") | G6: =IFERROR(IS!G6/IS!F6-1,"") | H6: =IFERROR(IS!H6/IS!G6-1,"") | I6: =IFERROR(IS!I6/IS!H6-1,"") | J6: =IFERROR(IS!J6/IS!I6-1,"") | K6: =IFERROR(IS!K6/IS!J6-1,"") | L6: =IFERROR(AVERAGE(G6:K6),K6) | M6: =IFERROR(AVERAGE(G6:K6),K6) | N6: =IFERROR(AVERAGE(G6:K6),K6) | O6: =IFERROR(AVERAGE(G6:K6),K6) | P6: =IFERROR(AVERAGE(G6:K6),K6)
A7: EBITDA margin % | B7: =IS!B15/IS!B6 | C7: =IS!C15/IS!C6 | D7: =IS!D15/IS!D6 | E7: =IS!E15/IS!E6 | F7: =IS!F15/IS!F6 | G7: =IS!G15/IS!G6 | H7: =IS!H15/IS!H6 | I7: =IS!I15/IS!I6 | ... K7: =IS!K15/IS!K6 | L7: =IFERROR(AVERAGE(G7:K7),K7) | M7: =IFERROR(AVERAGE(G7:K7),K7) | N7: =IFERROR(AVERAGE(G7:K7),K7) | O7: =IFERROR(AVERAGE(G7:K7),K7) | P7: =IFERROR(AVERAGE(G7:K7),K7)
A8: Depreciation & amortization (% of sales) | B8: =IS!B18/IS!B6 | C8: =IS!C18/IS!C6 | D8: =IS!D18/IS!D6 | E8: =IS!E18/IS!E6 | F8: =IS!F18/IS!F6 | G8: =IS!G18/IS!G6 | H8: =IS!H18/IS!H6 | I8: =IS!I18/IS!I6 | ... K8: =IS!K18/IS!K6 | L8: =IFERROR(AVERAGE(G8:K8),K8) | M8: =IFERROR(AVERAGE(G8:K8),K8) | N8: =IFERROR(AVERAGE(G8:K8),K8) | O8: =IFERROR(AVERAGE(G8:K8),K8) | P8: =IFERROR(AVERAGE(G8:K8),K8)
A9: Capital expenditure (% of sales) | C9: =IFERROR(((BS!C6+BS!C7)-(BS!B6+BS!B7)+IS!C18)/IS!C6,"") | D9: =IFERROR(((BS!D6+BS!D7)-(BS!C6+BS!C7)+IS!D18)/IS!D6,"") | E9: =IFERROR(((BS!E6+BS!E7)-(BS!D6+BS!D7)+IS!E18)/IS!E6,"") | F9: =IFERROR(((BS!F6+BS!F7)-(BS!E6+BS!E7)+IS!F18)/IS!F6,"") | G9: =IFERROR(((BS!G6+BS!G7)-(BS!F6+BS!F7)+IS!G18)/IS!G6,"") | H9: =IFERROR(((BS!H6+BS!H7)-(BS!G6+BS!G7)+IS!H18)/IS!H6,"") | I9: =IFERROR(((BS!I6+BS!I7)-(BS!H6+BS!H7)+IS!I18)/IS!I6,"") | J9: =IFERROR(((BS!J6+BS!J7)-(BS!I6+BS!I7)+IS!J18)/IS!J6,"") | K9: =IFERROR(((BS!K6+BS!K7)-(BS!J6+BS!J7)+IS!K18)/IS!K6,"") | L9: =IFERROR(AVERAGE(G9:K9),K9) | M9: =IFERROR(AVERAGE(G9:K9),K9) | N9: =IFERROR(AVERAGE(G9:K9),K9) | O9: =IFERROR(AVERAGE(G9:K9),K9) | P9: =IFERROR(AVERAGE(G9:K9),K9)
A10: Effective tax rate % | B10: =IS!B22/IS!B21 | C10: =IS!C22/IS!C21 | D10: =IS!D22/IS!D21 | E10: =IS!E22/IS!E21 | F10: =IS!F22/IS!F21 | G10: =IS!G22/IS!G21 | H10: =IS!H22/IS!H21 | I10: =IS!I22/IS!I21 | ... K10: =IS!K22/IS!K21 | L10: =IFERROR(AVERAGE(G10:K10),K10) | M10: =IFERROR(AVERAGE(G10:K10),K10) | N10: =IFERROR(AVERAGE(G10:K10),K10) | O10: =IFERROR(AVERAGE(G10:K10),K10) | P10: =IFERROR(AVERAGE(G10:K10),K10)
A11: Receivable days (DSO) | B11: =BS!B9/IS!B6*365 | C11: =BS!C9/IS!C6*365 | D11: =BS!D9/IS!D6*365 | E11: =BS!E9/IS!E6*365 | F11: =BS!F9/IS!F6*365 | G11: =BS!G9/IS!G6*365 | H11: =BS!H9/IS!H6*365 | I11: =BS!I9/IS!I6*365 | ... K11: =BS!K9/IS!K6*365 | L11: =IFERROR(AVERAGE(G11:K11),K11) | M11: =IFERROR(AVERAGE(G11:K11),K11) | N11: =IFERROR(AVERAGE(G11:K11),K11) | O11: =IFERROR(AVERAGE(G11:K11),K11) | P11: =IFERROR(AVERAGE(G11:K11),K11)
A12: Other liabilities (% of sales) | B12: =BS!B19/IS!B6 | C12: =BS!C19/IS!C6 | D12: =BS!D19/IS!D6 | E12: =BS!E19/IS!E6 | F12: =BS!F19/IS!F6 | G12: =BS!G19/IS!G6 | H12: =BS!H19/IS!H6 | I12: =BS!I19/IS!I6 | ... K12: =BS!K19/IS!K6 | L12: =IFERROR(AVERAGE(G12:K12),K12) | M12: =IFERROR(AVERAGE(G12:K12),K12) | N12: =IFERROR(AVERAGE(G12:K12),K12) | O12: =IFERROR(AVERAGE(G12:K12),K12) | P12: =IFERROR(AVERAGE(G12:K12),K12)
A13: Other assets, net (% of sales) | B13: =BS!B12/IS!B6 | C13: =BS!C12/IS!C6 | D13: =BS!D12/IS!D6 | E13: =BS!E12/IS!E6 | F13: =BS!F12/IS!F6 | G13: =BS!G12/IS!G6 | H13: =BS!H12/IS!H6 | I13: =BS!I12/IS!I6 | ... K13: =BS!K12/IS!K6 | L13: =IFERROR(AVERAGE(G13:K13),K13) | M13: =IFERROR(AVERAGE(G13:K13),K13) | N13: =IFERROR(AVERAGE(G13:K13),K13) | O13: =IFERROR(AVERAGE(G13:K13),K13) | P13: =IFERROR(AVERAGE(G13:K13),K13)
A14: Dividend payout ratio (% of PAT) | B14: =IS!B26/IS!B24 | C14: =IS!C26/IS!C24 | D14: =IS!D26/IS!D24 | E14: =IS!E26/IS!E24 | F14: =IS!F26/IS!F24 | G14: =IS!G26/IS!G24 | H14: =IS!H26/IS!H24 | I14: =IS!I26/IS!I24 | ... K14: =IS!K26/IS!K24 | L14: =IFERROR(AVERAGE(G14:K14),K14) | M14: =IFERROR(AVERAGE(G14:K14),K14) | N14: =IFERROR(AVERAGE(G14:K14),K14) | O14: =IFERROR(AVERAGE(G14:K14),K14) | P14: =IFERROR(AVERAGE(G14:K14),K14)
A15: Interest rate on borrowings (%) | C15: =IFERROR(IS!C20/AVERAGE(BS!B18,BS!C18),"") | D15: =IFERROR(IS!D20/AVERAGE(BS!C18,BS!D18),"") | E15: =IFERROR(IS!E20/AVERAGE(BS!D18,BS!E18),"") | F15: =IFERROR(IS!F20/AVERAGE(BS!E18,BS!F18),"") | G15: =IFERROR(IS!G20/AVERAGE(BS!F18,BS!G18),"") | H15: =IFERROR(IS!H20/AVERAGE(BS!G18,BS!H18),"") | I15: =IFERROR(IS!I20/AVERAGE(BS!H18,BS!I18),"") | J15: =IFERROR(IS!J20/AVERAGE(BS!I18,BS!J18),"") | K15: =IFERROR(IS!K20/AVERAGE(BS!J18,BS!K18),"") | L15: =IFERROR(AVERAGE(G15:K15),K15) | M15: =IFERROR(AVERAGE(G15:K15),K15) | N15: =IFERROR(AVERAGE(G15:K15),K15) | O15: =IFERROR(AVERAGE(G15:K15),K15) | P15: =IFERROR(AVERAGE(G15:K15),K15)
A16: Yield on cash & investments (%) | C16: =IFERROR(IS!C17/AVERAGE(BS!B11+BS!B8,BS!C11+BS!C8),"") | D16: =IFERROR(IS!D17/AVERAGE(BS!C11+BS!C8,BS!D11+BS!D8),"") | E16: =IFERROR(IS!E17/AVERAGE(BS!D11+BS!D8,BS!E11+BS!E8),"") | F16: =IFERROR(IS!F17/AVERAGE(BS!E11+BS!E8,BS!F11+BS!F8),"") | G16: =IFERROR(IS!G17/AVERAGE(BS!F11+BS!F8,BS!G11+BS!G8),"") | H16: =IFERROR(IS!H17/AVERAGE(BS!G11+BS!G8,BS!H11+BS!H8),"") | I16: =IFERROR(IS!I17/AVERAGE(BS!H11+BS!H8,BS!I11+BS!I8),"") | J16: =IFERROR(IS!J17/AVERAGE(BS!I11+BS!I8,BS!J11+BS!J8),"") | K16: =IFERROR(IS!K17/AVERAGE(BS!J11+BS!J8,BS!K11+BS!K8),"") | L16: =IFERROR(AVERAGE(G16:K16),K16) | M16: =IFERROR(AVERAGE(G16:K16),K16) | N16: =IFERROR(AVERAGE(G16:K16),K16) | O16: =IFERROR(AVERAGE(G16:K16),K16) | P16: =IFERROR(AVERAGE(G16:K16),K16)
A18: 2. COST OF CAPITAL (WACC) — SINGLE-POINT INPUTS
A19: Risk-free rate (India 10-Yr G-Sec yield) | C19: 0.0672
A20: Equity risk premium (India) | C20: 0.0361
A21: Levered beta | C21: 0.076
A22: Cost of equity (CAPM) = Rf + β × ERP | C22: =C19+C21*C20
A23: Pre-tax cost of debt | C23: 0.075
A24: Tax rate (for WACC) | C24: =K10
A25: After-tax cost of debt | C25: =C23*(1-C24)
A26: Market value of equity (current market cap, ₹ Cr) | C26: =C36
A27: Total debt (FY2026A, ₹ Cr) | C27: =BS!K18
A28: Weight of equity | C28: =C26/(C26+C27)
A29: Weight of debt | C29: =C27/(C26+C27)
A30: WACC | C30: =C28*C22+C29*C25
A32: Terminal growth rate (g) | C32: 0.05
A34: 3. CURRENT MARKET DATA
A35: Current share price (₹) | C35: 1932.6
A36: Market capitalization (₹ Cr) | C36: =C35*C37
A37: Shares outstanding (Cr) | C37: 239.93
A38: Face value per share (₹) | C38: 1

Sheet IS
A1: Income Statement
A2: SUN PHARMACEUTICAL INDUSTRIES LTD (Consolidated)
A4: INCOME STATEMENT
A5: (₹ Crore, unless stated otherwise) | B5: FY2017 | C5: FY2018 | D5: FY2019 | E5: FY2020 | F5: FY2021 | G5: FY2022 | H5: FY2023 | I5: FY2024 | J5: FY2025 | K5: FY2026 | L5: FY2027E | M5: FY2028E | N5: FY2029E | O5: FY2030E | P5: FY2031E
A6: Revenue from Operations | B6: 31578.44 | C6: 26489.46 | D6: 29065.91 | E6: 32837.5 | F6: 33498.14 | G6: 38654.49 | H6: 43885.68 | I6: 48496.85 | J6: 52578.44 | K6: 58462.04 | L6: =IS!K6*(1+Assumptions!L6) | M6: =IS!L6*(1+Assumptions!M6) | N6: =IS!M6*(1+Assumptions!N6) | O6: =IS!N6*(1+Assumptions!O6) | P6: =IS!O6*(1+Assumptions!P6)
A7: Growth % YoY | C7: =IFERROR(C6/B6-1,"") | D7: =IFERROR(D6/C6-1,"") | E7: =IFERROR(E6/D6-1,"") | F7: =IFERROR(F6/E6-1,"") | G7: =IFERROR(G6/F6-1,"") | H7: =IFERROR(H6/G6-1,"") | I7: =IFERROR(I6/H6-1,"") | J7: =IFERROR(J6/I6-1,"") | ... P7: =IFERROR(P6/O6-1,"")
A9: Operating Expenses
A10: Employee Costs | B10: 4902.3 | C10: 5367.05 | D10: 5967.09 | E10: 6362.35 | F10: 6862.23 | G10: 7300.83 | H10: 8296.03 | I10: 9429.06 | J10: 9973.12 | K10: 11418.86 | L10: n/a — modeled at aggregate EBITDA margin (see row 14) | M10: n/a — modeled at aggregate EBITDA margin (see row 14) | N10: n/a — modeled at aggregate EBITDA margin (see row 14) | O10: n/a — modeled at aggregate EBITDA margin (see row 14) | P10: n/a — modeled at aggregate EBITDA margin (see row 14)
A11: Cost of Materials & Other Direct Costs | B11: 10900.92 | C11: 9582.3 | D11: 10800.39 | E11: 11241.49 | F11: 11679.17 | G11: 13042.64 | H11: 14115.89 | I11: 13317.88 | J11: 13608.69 | K11: 14578.63 | L11: n/a — modeled at aggregate EBITDA margin (see row 14) | M11: n/a — modeled at aggregate EBITDA margin (see row 14) | N11: n/a — modeled at aggregate EBITDA margin (see row 14) | O11: n/a — modeled at aggregate EBITDA margin (see row 14) | P11: n/a — modeled at aggregate EBITDA margin (see row 14)
A12: Selling, General & Admin. Expenses | B12: 5224.61 | C12: 4727 | D12: 5350.33 | E12: 6995.37 | F12: 6283.41 | G12: 7366.88 | H12: 9482.36 | I12: 11033.19 | J12: 12222.92 | K12: 13831.14 | L12: n/a — modeled at aggregate EBITDA margin (see row 14) | M12: n/a — modeled at aggregate EBITDA margin (see row 14) | N12: n/a — modeled at aggregate EBITDA margin (see row 14) | O12: n/a — modeled at aggregate EBITDA margin (see row 14) | P12: n/a — modeled at aggregate EBITDA margin (see row 14)
A13: Other Expenses | B13: 720.22 | C13: 950.99 | D13: 1004.23 | E13: 954.6 | F13: 841.59 | G13: 794.18 | H13: 1027.87 | I13: 1406.82 | J13: 1508.94 | K13: 1789.45 | L13: n/a — modeled at aggregate EBITDA margin (see row 14) | M13: n/a — modeled at aggregate EBITDA margin (see row 14) | N13: n/a — modeled at aggregate EBITDA margin (see row 14) | O13: n/a — modeled at aggregate EBITDA margin (see row 14) | P13: n/a — modeled at aggregate EBITDA margin (see row 14)
A14: Total Operating Expenses | B14: =SUM(B10:B13) | C14: =SUM(C10:C13) | D14: =SUM(D10:D13) | E14: =SUM(E10:E13) | F14: =SUM(F10:F13) | G14: =SUM(G10:G13) | H14: =SUM(H10:H13) | I14: =SUM(I10:I13) | ... K14: =SUM(K10:K13) | L14: =IS!L6*(1-Assumptions!L7) | M14: =IS!M6*(1-Assumptions!M7) | N14: =IS!N6*(1-Assumptions!N7) | O14: =IS!O6*(1-Assumptions!O7) | P14: =IS!P6*(1-Assumptions!P7)
A15: EBITDA | B15: =B6-B14 | C15: =C6-C14 | D15: =D6-D14 | E15: =E6-E14 | F15: =F6-F14 | G15: =G6-G14 | H15: =H6-H14 | I15: =I6-I14 | ... P15: =P6-P14
A16: EBITDA Margin % | B16: =B15/B6 | C16: =C15/C6 | D16: =D15/D6 | E16: =E15/E6 | F16: =F15/F6 | G16: =G15/G6 | H16: =H15/H6 | I16: =I15/I6 | ... P16: =P15/P6
A17: Other Income | B17: 610.4 | C17: -135.03 | D17: -258.28 | E17: 382.26 | F17: -3449.21 | G17: -3505.16 | H17: 459.42 | I17: 865.23 | J17: 1444.42 | K17: 1894.81 | L17: =Assumptions!L16*(BS!K11+BS!K8) | M17: =Assumptions!M16*(BS!L11+BS!L8) | N17: =Assumptions!N16*(BS!M11+BS!M8) | O17: =Assumptions!O16*(BS!N11+BS!N8) | P17: =Assumptions!P16*(BS!O11+BS!O8)
A18: Less: Depreciation & Amortization | B18: 1264.75 | C18: 1499.84 | D18: 1753.25 | E18: 2052.78 | F18: 2079.95 | G18: 2143.74 | H18: 2529.43 | I18: 2556.64 | J18: 2575.39 | K18: 2937.85 | L18: =Assumptions!L8*L6 | M18: =Assumptions!M8*M6 | N18: =Assumptions!N8*N6 | O18: =Assumptions!O8*O6 | P18: =Assumptions!P8*P6
A19: EBIT | B19: =B15-B18 | C19: =C15-C18 | D19: =D15-D18 | E19: =E15-E18 | F19: =F15-F18 | G19: =G15-G18 | H19: =H15-H18 | I19: =I15-I18 | ... P19: =P15-P18
A20: Less: Interest Expense | B20: 399.8 | C20: 517.57 | D20: 555.25 | E20: 302.73 | F20: 141.43 | G20: 127.35 | H20: 172 | I20: 238.47 | J20: 231.36 | K20: 338.91 | L20: =Assumptions!L15*BS!K18 | M20: =Assumptions!M15*BS!L18 | N20: =Assumptions!N15*BS!M18 | O20: =Assumptions!O15*BS!N18 | P20: =Assumptions!P15*BS!O18
A21: Profit Before Tax (PBT) | B21: =B19+B17-B20 | C21: =C19+C17-C20 | D21: =D19+D17-D20 | E21: =E19+E17-E20 | F21: =F19+F17-F20 | G21: =G19+G17-G20 | H21: =H19+H17-H20 | I21: =I19+I17-I20 | ... P21: =P19+P17-P20
A22: Less: Tax Expense | B22: 1211.57 | C22: 911.04 | D22: 600.88 | E22: 822.8 | F22: 514.69 | G22: 1075.5 | H22: 847.59 | I22: 1439.45 | J22: 2772.03 | K22: 3554.36 | L22: =Assumptions!L10*L21 | M22: =Assumptions!M10*M21 | N22: =Assumptions!N10*N21 | O22: =Assumptions!O10*O21 | P22: =Assumptions!P10*P21
A23: Effective Tax Rate % | B23: =B22/B21 | C23: =C22/C21 | D23: =D22/D21 | E23: =E22/E21 | F23: =F22/F21 | G23: =G22/G21 | H23: =H22/H21 | I23: =I22/I21 | ... P23: =P22/P21
A24: Net Profit After Tax (PAT) | B24: =B21-B22 | C24: =C21-C22 | D24: =D21-D22 | E24: =E21-E22 | F24: =F21-F22 | G24: =G21-G22 | H24: =H21-H22 | I24: =I21-I22 | ... P24: =P21-P22
A25: Net Profit Margin % | B25: =B24/B6 | C25: =C24/C6 | D25: =D24/D6 | E25: =E24/E6 | F25: =F24/F6 | G25: =G24/G6 | H25: =H24/H6 | I25: =I24/I6 | ... P25: =P24/P6
A26: Dividends Paid | B26: 839.76 | C26: 479.86 | D26: 659.81 | E26: 959.72 | F26: 1799.48 | G26: 2399.3 | H26: 2759.2 | I26: 3239.06 | J26: 3838.88 | K26: 3838.88 | L26: =Assumptions!L14*L24 | M26: =Assumptions!M14*M24 | N26: =Assumptions!N14*N24 | O26: =Assumptions!O14*O24 | P26: =Assumptions!P14*P24
A27: Retained Earnings | B27: =B24-B26 | C27: =C24-C26 | D27: =D24-D26 | E27: =E24-E26 | F27: =F24-F26 | G27: =G24-G26 | H27: =H24-H26 | I27: =I24-I26 | ... P27: =P24-P26
A29: PER SHARE DATA
A30: Weighted Avg. Shares Outstanding (Cr) | B30: 239.93 | C30: 239.93 | D30: 239.93 | E30: 239.93 | F30: 239.93 | G30: 239.93 | H30: 239.93 | I30: 239.93 | J30: 239.93 | K30: 239.93 | L30: =Assumptions!$C$37 | M30: =Assumptions!$C$37 | N30: =Assumptions!$C$37 | O30: =Assumptions!$C$37 | P30: =Assumptions!$C$37
A31: Earnings Per Share — Basic (₹) | B31: =B24/B30 | C31: =C24/C30 | D31: =D24/D30 | E31: =E24/E30 | F31: =F24/F30 | G31: =G24/G30 | H31: =H24/H30 | I31: =I24/I30 | ... P31: =P24/P30
A32: Dividend Per Share (₹) | B32: =B26/B30 | C32: =C26/C30 | D32: =D26/D30 | E32: =E26/E30 | F32: =F26/F30 | G32: =G26/G30 | H32: =H26/H30 | I32: =I26/I30 | ... P32: =P26/P30

Sheet BS
A1: Balance Sheet
A2: SUN PHARMACEUTICAL INDUSTRIES LTD (Consolidated)
A4: ASSETS
A5: (₹ Crore, unless stated otherwise) | B5: FY2017 | C5: FY2018 | D5: FY2019 | E5: FY2020 | F5: FY2021 | G5: FY2022 | H5: FY2023 | I5: FY2024 | J5: FY2025 | K5: FY2026 | L5: FY2027E | M5: FY2028E | N5: FY2029E | O5: FY2030E | P5: FY2031E
A6: Net Block (Fixed Assets) | B6: 17675.17 | C6: 18852.65 | D6: 21836.54 | E6: 22846.91 | F6: 21552.98 | G6: 22665.16 | H6: 24065.44 | I6: 23248.15 | J6: 22586.28 | K6: 32822.27 | L6: =K6+Assumptions!L9*IS!L6-IS!L18 | M6: =L6+Assumptions!M9*IS!M6-IS!M18 | N6: =M6+Assumptions!N9*IS!N6-IS!N18 | O6: =N6+Assumptions!O9*IS!O6-IS!O18 | P6: =O6+Assumptions!P9*IS!P6-IS!P18
A7: Capital Work-in-Progress | B7: 2801.38 | C7: 2465.16 | D7: 1411.15 | E7: 1220.34 | F7: 1566.83 | G7: 1286.8 | H7: 4973.16 | I7: 5353.88 | J7: 6643.96 | K7: 3051.73 | L7: =K7 | M7: =L7 | N7: =M7 | O7: =N7 | P7: =O7
A8: Investments | B8: 1191.88 | C8: 7142.87 | D8: 7902.53 | E8: 10143.11 | F8: 9612.45 | G8: 12848.59 | H8: 14824.34 | I8: 15025.77 | J8: 18353.8 | K8: 24722.52 | L8: =K8*(1+Assumptions!L6) | M8: =L8*(1+Assumptions!M6) | N8: =M8*(1+Assumptions!N6) | O8: =N8*(1+Assumptions!O6) | P8: =O8*(1+Assumptions!P6)
A9: Trade Receivables | B9: 7202.61 | C9: 7815.28 | D9: 8884.2 | E9: 9421.24 | F9: 9061.4 | G9: 10484.59 | H9: 11438.51 | I9: 11249.37 | J9: 13046.11 | K9: 15509.67 | L9: =Assumptions!L11/365*IS!L6 | M9: =Assumptions!M11/365*IS!M6 | N9: =Assumptions!N11/365*IS!N6 | O9: =Assumptions!O11/365*IS!O6 | P9: =Assumptions!P11/365*IS!P6
A10: Inventory | B10: 6832.81 | C10: 6880.69 | D10: 7885.98 | E10: 7874.99 | F10: 8997.02 | G10: 8925.13 | H10: 10513.05 | I10: 9868.29 | J10: 10243.33 | K10: 11492.93 | L10: =K10 | M10: =L10 | N10: =M10 | O10: =N10 | P10: =O10
A11: Cash & Bank Balances | B11: 15140.84 | C11: 9929.38 | D11: 7275.6 | E11: 6487.55 | F11: 6445.51 | G11: 5033.35 | H11: 5770.29 | I11: 10520.68 | J11: 11331.62 | K11: 11603.08 | L11: =CF!L30 | M11: =CF!M30 | N11: =CF!N30 | O11: =CF!O30 | P11: =CF!P30
A12: Other Assets, net (unbilled rev., prepaid, DTA, other) | B12: 10250.76 | C12: 11211.36 | D12: 9393.53 | E12: 10200.18 | F12: 10386.03 | G12: 8532.29 | H12: 9127.11 | I12: 10061.65 | J12: 9703.04 | K12: 9205 | L12: =Assumptions!L13*IS!L6 | M12: =Assumptions!M13*IS!M6 | N12: =Assumptions!N13*IS!N6 | O12: =Assumptions!O13*IS!O6 | P12: =Assumptions!P13*IS!P6
A13: Total Assets | B13: =SUM(B6:B12) | C13: =SUM(C6:C12) | D13: =SUM(D6:D12) | E13: =SUM(E6:E12) | F13: =SUM(F6:F12) | G13: =SUM(G6:G12) | H13: =SUM(H6:H12) | I13: =SUM(I6:I12) | ... P13: =SUM(P6:P12)
A15: LIABILITIES & EQUITY
A16: Equity Share Capital | B16: 239.93 | C16: 239.93 | D16: 239.93 | E16: 239.93 | F16: 239.93 | G16: 239.93 | H16: 239.93 | I16: 239.93 | J16: 239.93 | K16: 239.93 | L16: =K16 | M16: =L16 | N16: =M16 | O16: =N16 | P16: =O16
A17: Reserves & Surplus | B17: 36399.74 | C17: 38074.18 | D17: 41169.13 | E17: 45024.52 | F17: 46222.85 | G17: 47771.29 | H17: 55755.45 | I17: 63426.82 | J17: 71978.09 | K17: 83330.16 | L17: =K17+IS!L24-IS!L26 | M17: =L17+IS!M24-IS!M26 | N17: =M17+IS!N24-IS!N26 | O17: =N17+IS!O24-IS!O26 | P17: =O17+IS!P24-IS!P26
A18: Borrowings | B18: 9831.77 | C18: 10385.27 | D18: 10514.36 | E18: 8314.88 | F18: 3868.58 | G18: 1290.3 | H18: 6885.87 | I18: 3273.67 | J18: 2362.19 | K18: 4627.32 | L18: =K18 | M18: =L18 | N18: =M18 | O18: =N18 | P18: =O18
A19: Other Liabilities & Provisions | B19: 14624.01 | C19: 15598.01 | D19: 12666.11 | E19: 14614.99 | F19: 17290.86 | G19: 20474.39 | H19: 17830.65 | I19: 18387.37 | J19: 17327.93 | K19: 20209.79 | L19: =Assumptions!L12*IS!L6 | M19: =Assumptions!M12*IS!M6 | N19: =Assumptions!N12*IS!N6 | O19: =Assumptions!O12*IS!O6 | P19: =Assumptions!P12*IS!P6
A20: Total Liabilities & Equity | B20: =SUM(B16:B19) | C20: =SUM(C16:C19) | D20: =SUM(D16:D19) | E20: =SUM(E16:E19) | F20: =SUM(F16:F19) | G20: =SUM(G16:G19) | H20: =SUM(H16:H19) | I20: =SUM(I16:I19) | ... P20: =SUM(P16:P19)
A22: Balance Check (Assets − Liab. & Equity) | B22: =B13-B20 | C22: =C13-C20 | D22: =D13-D20 | E22: =E13-E20 | F22: =F13-F20 | G22: =G13-G20 | H22: =H13-H20 | I22: =I13-I20 | ... P22: =P13-P20
A24: WORKING CAPITAL & OTHER MEMO ITEMS
A25: Net Working Capital (Receiv. + Inv. − Other Liab.) | B25: =B9+B10-B19 | C25: =C9+C10-C19 | D25: =D9+D10-D19 | E25: =E9+E10-E19 | F25: =F9+F10-F19 | G25: =G9+G10-G19 | H25: =H9+H10-H19 | I25: =I9+I10-I19 | ... P25: =P9+P10-P19
A26: Net Debt / (Net Cash) | B26: =B18-B11-B8 | C26: =C18-C11-C8 | D26: =D18-D11-D8 | E26: =E18-E11-E8 | F26: =F18-F11-F8 | G26: =G18-G11-G8 | H26: =H18-H11-H8 | I26: =I18-I11-I8 | ... P26: =P18-P11-P8
A27: Book Value Per Share (₹) | B27: =(B16+B17)/IS!B30 | C27: =(C16+C17)/IS!C30 | D27: =(D16+D17)/IS!D30 | E27: =(E16+E17)/IS!E30 | F27: =(F16+F17)/IS!F30 | G27: =(G16+G17)/IS!G30 | H27: =(H16+H17)/IS!H30 | I27: =(I16+I17)/IS!I30 | ... P27: =(P16+P17)/IS!P30

Sheet CF
A1: Cash Flow Statement
A2: SUN PHARMACEUTICAL INDUSTRIES LTD (Consolidated)
A4: A. CASH FLOW — AS REPORTED (HISTORICAL ACTUALS)
A5: (₹ Crore, unless stated otherwise) | B5: FY2017 | C5: FY2018 | D5: FY2019 | E5: FY2020 | F5: FY2021 | G5: FY2022 | H5: FY2023 | I5: FY2024 | J5: FY2025 | K5: FY2026 | L5: FY2027E | M5: FY2028E | N5: FY2029E | O5: FY2030E | P5: FY2031E
A6: Cash Flow from Operating Activities | B6: 7082.21 | C6: 3907.15 | D6: 2196.45 | E6: 6554.77 | F6: 6170.37 | G6: 8984.54 | H6: 4959.33 | I6: 12134.98 | J6: 14072.09 | K6: 12419.18 | L6: — | M6: — | N6: — | O6: — | P6: —
A7: Cash Flow from Investing Activities | B7: -4186.15 | C7: -3103.8 | D7: -310.08 | E7: -2225.32 | F7: 406.53 | G7: -5555.86 | H7: -7219.92 | I7: -762.9 | J7: -5183.15 | K7: -10404.89 | L7: — | M7: — | N7: — | O7: — | P7: —
A8: Cash Flow from Financing Activities | B8: -2285.39 | C8: -1539.26 | D8: -2730.52 | E8: -5715.14 | F8: -5980.48 | G8: -5193.46 | H8: 2376.07 | I8: -6710.16 | J8: -7905.82 | K8: -2512.55 | L8: — | M8: — | N8: — | O8: — | P8: —
A9: Net Increase / (Decrease) in Cash | B9: =SUM(B6:B8) | C9: =SUM(C6:C8) | D9: =SUM(D6:D8) | E9: =SUM(E6:E8) | F9: =SUM(F6:F8) | G9: =SUM(G6:G8) | H9: =SUM(H6:H8) | I9: =SUM(I6:I8) | ... K9: =SUM(K6:K8) | L9: — | M9: — | N9: — | O9: — | P9: —
A10: Opening Cash Balance | B10: n/a | C10: =BS!B11 | D10: =BS!C11 | E10: =BS!D11 | F10: =BS!E11 | G10: =BS!F11 | H10: =BS!G11 | I10: =BS!H11 | J10: =BS!I11 | K10: =BS!J11 | L10: — | M10: — | N10: — | O10: — | P10: —
A11: Closing Cash Balance (check vs. Balance Sheet) | B11: n/a | C11: =C10+C9-BS!C11 | D11: =D10+D9-BS!D11 | E11: =E10+E9-BS!E11 | F11: =F10+F9-BS!F11 | G11: =G10+G9-BS!G11 | H11: =H10+H9-BS!H11 | I11: =I10+I9-BS!I11 | J11: =J10+J9-BS!J11 | K11: =K10+K9-BS!K11 | L11: — | M11: — | N11: — | O11: — | P11: —
A13: B. CASH FLOW — PROJECTED / MODEL-DERIVED (INDIRECT METHOD, ALL PERIODS)
A14: (₹ Crore, unless stated otherwise) | B14: FY2017 | C14: FY2018 | D14: FY2019 | E14: FY2020 | F14: FY2021 | G14: FY2022 | H14: FY2023 | I14: FY2024 | J14: FY2025 | K14: FY2026 | L14: FY2027E | M14: FY2028E | N14: FY2029E | O14: FY2030E | P14: FY2031E
A15: Net Profit After Tax | B15: =IS!B24 | C15: =IS!C24 | D15: =IS!D24 | E15: =IS!E24 | F15: =IS!F24 | G15: =IS!G24 | H15: =IS!H24 | I15: =IS!I24 | ... P15: =IS!P24
A16: Add: Depreciation & Amortization | B16: =IS!B18 | C16: =IS!C18 | D16: =IS!D18 | E16: =IS!E18 | F16: =IS!F18 | G16: =IS!G18 | H16: =IS!H18 | I16: =IS!I18 | ... P16: =IS!P18
A17: Less: (Incr.)/Decr. in Receivables | B17: n/a | C17: =-(BS!C9-BS!B9) | D17: =-(BS!D9-BS!C9) | E17: =-(BS!E9-BS!D9) | F17: =-(BS!F9-BS!E9) | G17: =-(BS!G9-BS!F9) | H17: =-(BS!H9-BS!G9) | I17: =-(BS!I9-BS!H9) | J17: =-(BS!J9-BS!I9) | ... P17: =-(BS!P9-BS!O9)
A18: Less: (Incr.)/Decr. in Inventory | B18: n/a | C18: =-(BS!C10-BS!B10) | D18: =-(BS!D10-BS!C10) | E18: =-(BS!E10-BS!D10) | F18: =-(BS!F10-BS!E10) | G18: =-(BS!G10-BS!F10) | H18: =-(BS!H10-BS!G10) | I18: =-(BS!I10-BS!H10) | J18: =-(BS!J10-BS!I10) | ... P18: =-(BS!P10-BS!O10)
A19: Less: (Incr.)/Decr. in Other Assets | B19: n/a | C19: =-(BS!C12-BS!B12) | D19: =-(BS!D12-BS!C12) | E19: =-(BS!E12-BS!D12) | F19: =-(BS!F12-BS!E12) | G19: =-(BS!G12-BS!F12) | H19: =-(BS!H12-BS!G12) | I19: =-(BS!I12-BS!H12) | J19: =-(BS!J12-BS!I12) | ... P19: =-(BS!P12-BS!O12)
A20: Add: Incr./(Decr.) in Other Liabilities | B20: n/a | C20: =(BS!C19-BS!B19) | D20: =(BS!D19-BS!C19) | E20: =(BS!E19-BS!D19) | F20: =(BS!F19-BS!E19) | G20: =(BS!G19-BS!F19) | H20: =(BS!H19-BS!G19) | I20: =(BS!I19-BS!H19) | J20: =(BS!J19-BS!I19) | ... P20: =(BS!P19-BS!O19)
A21: Cash Flow from Operating Activities (derived) | B21: n/a | C21: =SUM(C15:C20) | D21: =SUM(D15:D20) | E21: =SUM(E15:E20) | F21: =SUM(F15:F20) | G21: =SUM(G15:G20) | H21: =SUM(H15:H20) | I21: =SUM(I15:I20) | J21: =SUM(J15:J20) | ... P21: =SUM(P15:P20)
A22: Less: Capital Expenditure | B22: n/a | C22: =-((BS!C6+BS!C7)-(BS!B6+BS!B7)+IS!C18) | D22: =-((BS!D6+BS!D7)-(BS!C6+BS!C7)+IS!D18) | E22: =-((BS!E6+BS!E7)-(BS!D6+BS!D7)+IS!E18) | F22: =-((BS!F6+BS!F7)-(BS!E6+BS!E7)+IS!F18) | G22: =-((BS!G6+BS!G7)-(BS!F6+BS!F7)+IS!G18) | H22: =-((BS!H6+BS!H7)-(BS!G6+BS!G7)+IS!H18) | I22: =-((BS!I6+BS!I7)-(BS!H6+BS!H7)+IS!I18) | J22: =-((BS!J6+BS!J7)-(BS!I6+BS!I7)+IS!J18) | ... P22: =-((BS!P6+BS!P7)-(BS!O6+BS!O7)+IS!P18)
A23: Less: Incr. in Investments | B23: n/a | C23: =-(BS!C8-BS!B8) | D23: =-(BS!D8-BS!C8) | E23: =-(BS!E8-BS!D8) | F23: =-(BS!F8-BS!E8) | G23: =-(BS!G8-BS!F8) | H23: =-(BS!H8-BS!G8) | I23: =-(BS!I8-BS!H8) | J23: =-(BS!J8-BS!I8) | ... P23: =-(BS!P8-BS!O8)
A24: Cash Flow from Investing Activities (derived) | B24: n/a | C24: =SUM(C22:C23) | D24: =SUM(D22:D23) | E24: =SUM(E22:E23) | F24: =SUM(F22:F23) | G24: =SUM(G22:G23) | H24: =SUM(H22:H23) | I24: =SUM(I22:I23) | J24: =SUM(J22:J23) | ... P24: =SUM(P22:P23)
A25: Add: Incr./(Decr.) in Borrowings | B25: n/a | C25: =(BS!C18-BS!B18) | D25: =(BS!D18-BS!C18) | E25: =(BS!E18-BS!D18) | F25: =(BS!F18-BS!E18) | G25: =(BS!G18-BS!F18) | H25: =(BS!H18-BS!G18) | I25: =(BS!I18-BS!H18) | J25: =(BS!J18-BS!I18) | ... P25: =(BS!P18-BS!O18)
A26: Less: Dividends Paid | B26: =-IS!B26 | C26: =-IS!C26 | D26: =-IS!D26 | E26: =-IS!E26 | F26: =-IS!F26 | G26: =-IS!G26 | H26: =-IS!H26 | I26: =-IS!I26 | ... P26: =-IS!P26
A27: Cash Flow from Financing Activities (derived) | B27: n/a | C27: =SUM(C25:C26) | D27: =SUM(D25:D26) | E27: =SUM(E25:E26) | F27: =SUM(F25:F26) | G27: =SUM(G25:G26) | H27: =SUM(H25:H26) | I27: =SUM(I25:I26) | J27: =SUM(J25:J26) | ... P27: =SUM(P25:P26)
A28: Net Increase / (Decrease) in Cash (derived) | B28: n/a | C28: =C21+C24+C27 | D28: =D21+D24+D27 | E28: =E21+E24+E27 | F28: =F21+F24+F27 | G28: =G21+G24+G27 | H28: =H21+H24+H27 | I28: =I21+I24+I27 | J28: =J21+J24+J27 | ... P28: =P21+P24+P27
A29: Opening Cash Balance | B29: n/a | C29: =BS!B11 | D29: =BS!C11 | E29: =BS!D11 | F29: =BS!E11 | G29: =BS!F11 | H29: =BS!G11 | I29: =BS!H11 | J29: =BS!I11 | ... L29: =BS!K11 | M29: =L30 | N29: =M30 | O29: =N30 | P29: =O30
A30: Closing Cash Balance (derived) | B30: n/a | C30: =C29+C28 | D30: =D29+D28 | E30: =E29+E28 | F30: =F29+F28 | G30: =G29+G28 | H30: =H29+H28 | I30: =I29+I28 | J30: =J29+J28 | ... P30: =P29+P28
A32: Free Cash Flow to Firm (memo) — see DCF sheet for full build

Sheet Ratios
A1: Ratio Analysis
A2: SUN PHARMACEUTICAL INDUSTRIES LTD (Consolidated)
A4: GROWTH
A5: (₹ Crore, unless stated otherwise) | B5: FY2017 | C5: FY2018 | D5: FY2019 | E5: FY2020 | F5: FY2021 | G5: FY2022 | H5: FY2023 | I5: FY2024 | J5: FY2025 | K5: FY2026 | L5: FY2027E | M5: FY2028E | N5: FY2029E | O5: FY2030E | P5: FY2031E
A6: Revenue Growth % YoY | C6: =IS!C7 | D6: =IS!D7 | E6: =IS!E7 | F6: =IS!F7 | G6: =IS!G7 | H6: =IS!H7 | I6: =IS!I7 | J6: =IS!J7 | ... P6: =IS!P7
A7: EBITDA Growth % YoY | C7: =IFERROR(IS!C15/IS!B15-1,"") | D7: =IFERROR(IS!D15/IS!C15-1,"") | E7: =IFERROR(IS!E15/IS!D15-1,"") | F7: =IFERROR(IS!F15/IS!E15-1,"") | G7: =IFERROR(IS!G15/IS!F15-1,"") | H7: =IFERROR(IS!H15/IS!G15-1,"") | I7: =IFERROR(IS!I15/IS!H15-1,"") | J7: =IFERROR(IS!J15/IS!I15-1,"") | ... P7: =IFERROR(IS!P15/IS!O15-1,"")
A8: Net Profit Growth % YoY | C8: =IFERROR(IS!C24/IS!B24-1,"") | D8: =IFERROR(IS!D24/IS!C24-1,"") | E8: =IFERROR(IS!E24/IS!D24-1,"") | F8: =IFERROR(IS!F24/IS!E24-1,"") | G8: =IFERROR(IS!G24/IS!F24-1,"") | H8: =IFERROR(IS!H24/IS!G24-1,"") | I8: =IFERROR(IS!I24/IS!H24-1,"") | J8: =IFERROR(IS!J24/IS!I24-1,"") | ... P8: =IFERROR(IS!P24/IS!O24-1,"")
A9: EPS Growth % YoY | C9: =IFERROR(IS!C31/IS!B31-1,"") | D9: =IFERROR(IS!D31/IS!C31-1,"") | E9: =IFERROR(IS!E31/IS!D31-1,"") | F9: =IFERROR(IS!F31/IS!E31-1,"") | G9: =IFERROR(IS!G31/IS!F31-1,"") | H9: =IFERROR(IS!H31/IS!G31-1,"") | I9: =IFERROR(IS!I31/IS!H31-1,"") | J9: =IFERROR(IS!J31/IS!I31-1,"") | ... P9: =IFERROR(IS!P31/IS!O31-1,"")
A11: PROFITABILITY
A12: EBITDA Margin % | B12: =IS!B16 | C12: =IS!C16 | D12: =IS!D16 | E12: =IS!E16 | F12: =IS!F16 | G12: =IS!G16 | H12: =IS!H16 | I12: =IS!I16 | ... P12: =IS!P16
A13: EBIT Margin % | B13: =IS!B19/IS!B6 | C13: =IS!C19/IS!C6 | D13: =IS!D19/IS!D6 | E13: =IS!E19/IS!E6 | F13: =IS!F19/IS!F6 | G13: =IS!G19/IS!G6 | H13: =IS!H19/IS!H6 | I13: =IS!I19/IS!I6 | ... P13: =IS!P19/IS!P6
A14: Net Profit Margin % | B14: =IS!B25 | C14: =IS!C25 | D14: =IS!D25 | E14: =IS!E25 | F14: =IS!F25 | G14: =IS!G25 | H14: =IS!H25 | I14: =IS!I25 | ... P14: =IS!P25
A15: Return on Equity (ROE) % | B15: =IS!B24/(BS!B16+BS!B17) | C15: =IFERROR(IS!C24/AVERAGE(BS!B16+BS!B17,BS!C16+BS!C17),"") | D15: =IFERROR(IS!D24/AVERAGE(BS!C16+BS!C17,BS!D16+BS!D17),"") | E15: =IFERROR(IS!E24/AVERAGE(BS!D16+BS!D17,BS!E16+BS!E17),"") | F15: =IFERROR(IS!F24/AVERAGE(BS!E16+BS!E17,BS!F16+BS!F17),"") | G15: =IFERROR(IS!G24/AVERAGE(BS!F16+BS!F17,BS!G16+BS!G17),"") | H15: =IFERROR(IS!H24/AVERAGE(BS!G16+BS!G17,BS!H16+BS!H17),"") | I15: =IFERROR(IS!I24/AVERAGE(BS!H16+BS!H17,BS!I16+BS!I17),"") | J15: =IFERROR(IS!J24/AVERAGE(BS!I16+BS!I17,BS!J16+BS!J17),"") | ... P15: =IFERROR(IS!P24/AVERAGE(BS!O16+BS!O17,BS!P16+BS!P17),"")
A16: Return on Capital Employed (ROCE) % | B16: =IS!B19/(BS!B16+BS!B17+BS!B18) | C16: =IFERROR(IS!C19/AVERAGE(BS!B16+BS!B17+BS!B18,BS!C16+BS!C17+BS!C18),"") | D16: =IFERROR(IS!D19/AVERAGE(BS!C16+BS!C17+BS!C18,BS!D16+BS!D17+BS!D18),"") | E16: =IFERROR(IS!E19/AVERAGE(BS!D16+BS!D17+BS!D18,BS!E16+BS!E17+BS!E18),"") | F16: =IFERROR(IS!F19/AVERAGE(BS!E16+BS!E17+BS!E18,BS!F16+BS!F17+BS!F18),"") | G16: =IFERROR(IS!G19/AVERAGE(BS!F16+BS!F17+BS!F18,BS!G16+BS!G17+BS!G18),"") | H16: =IFERROR(IS!H19/AVERAGE(BS!G16+BS!G17+BS!G18,BS!H16+BS!H17+BS!H18),"") | I16: =IFERROR(IS!I19/AVERAGE(BS!H16+BS!H17+BS!H18,BS!I16+BS!I17+BS!I18),"") | J16: =IFERROR(IS!J19/AVERAGE(BS!I16+BS!I17+BS!I18,BS!J16+BS!J17+BS!J18),"") | ... P16: =IFERROR(IS!P19/AVERAGE(BS!O16+BS!O17+BS!O18,BS!P16+BS!P17+BS!P18),"")
A17: Return on Assets (ROA) % | B17: =IS!B24/BS!B13 | C17: =IFERROR(IS!C24/AVERAGE(BS!B13,BS!C13),"") | D17: =IFERROR(IS!D24/AVERAGE(BS!C13,BS!D13),"") | E17: =IFERROR(IS!E24/AVERAGE(BS!D13,BS!E13),"") | F17: =IFERROR(IS!F24/AVERAGE(BS!E13,BS!F13),"") | G17: =IFERROR(IS!G24/AVERAGE(BS!F13,BS!G13),"") | H17: =IFERROR(IS!H24/AVERAGE(BS!G13,BS!H13),"") | I17: =IFERROR(IS!I24/AVERAGE(BS!H13,BS!I13),"") | J17: =IFERROR(IS!J24/AVERAGE(BS!I13,BS!J13),"") | ... P17: =IFERROR(IS!P24/AVERAGE(BS!O13,BS!P13),"")
A19: EFFICIENCY
A20: Receivable Days (DSO) | B20: =BS!B9/IS!B6*365 | C20: =BS!C9/IS!C6*365 | D20: =BS!D9/IS!D6*365 | E20: =BS!E9/IS!E6*365 | F20: =BS!F9/IS!F6*365 | G20: =BS!G9/IS!G6*365 | H20: =BS!H9/IS!H6*365 | I20: =BS!I9/IS!I6*365 | ... P20: =BS!P9/IS!P6*365
A21: Asset Turnover (x) | B21: =IS!B6/BS!B13 | C21: =IS!C6/BS!C13 | D21: =IS!D6/BS!D13 | E21: =IS!E6/BS!E13 | F21: =IS!F6/BS!F13 | G21: =IS!G6/BS!G13 | H21: =IS!H6/BS!H13 | I21: =IS!I6/BS!I13 | ... P21: =IS!P6/BS!P13
A22: Fixed Asset Turnover (x) | B22: =IS!B6/(BS!B6+BS!B7) | C22: =IS!C6/(BS!C6+BS!C7) | D22: =IS!D6/(BS!D6+BS!D7) | E22: =IS!E6/(BS!E6+BS!E7) | F22: =IS!F6/(BS!F6+BS!F7) | G22: =IS!G6/(BS!G6+BS!G7) | H22: =IS!H6/(BS!H6+BS!H7) | I22: =IS!I6/(BS!I6+BS!I7) | ... P22: =IS!P6/(BS!P6+BS!P7)
A24: LEVERAGE & COVERAGE
A25: Debt / Equity (x) | B25: =BS!B18/(BS!B16+BS!B17) | C25: =BS!C18/(BS!C16+BS!C17) | D25: =BS!D18/(BS!D16+BS!D17) | E25: =BS!E18/(BS!E16+BS!E17) | F25: =BS!F18/(BS!F16+BS!F17) | G25: =BS!G18/(BS!G16+BS!G17) | H25: =BS!H18/(BS!H16+BS!H17) | I25: =BS!I18/(BS!I16+BS!I17) | ... P25: =BS!P18/(BS!P16+BS!P17)
A26: Debt / EBITDA (x) | B26: =BS!B18/IS!B15 | C26: =BS!C18/IS!C15 | D26: =BS!D18/IS!D15 | E26: =BS!E18/IS!E15 | F26: =BS!F18/IS!F15 | G26: =BS!G18/IS!G15 | H26: =BS!H18/IS!H15 | I26: =BS!I18/IS!I15 | ... P26: =BS!P18/IS!P15
A27: Interest Coverage Ratio (x) | B27: =IFERROR(IS!B19/IS!B20,"") | C27: =IFERROR(IS!C19/IS!C20,"") | D27: =IFERROR(IS!D19/IS!D20,"") | E27: =IFERROR(IS!E19/IS!E20,"") | F27: =IFERROR(IS!F19/IS!F20,"") | G27: =IFERROR(IS!G19/IS!G20,"") | H27: =IFERROR(IS!H19/IS!H20,"") | I27: =IFERROR(IS!I19/IS!I20,"") | ... P27: =IFERROR(IS!P19/IS!P20,"")
A28: Net Debt / EBITDA (x) | B28: =BS!B26/IS!B15 | C28: =BS!C26/IS!C15 | D28: =BS!D26/IS!D15 | E28: =BS!E26/IS!E15 | F28: =BS!F26/IS!F15 | G28: =BS!G26/IS!G15 | H28: =BS!H26/IS!H15 | I28: =BS!I26/IS!I15 | ... P28: =BS!P26/IS!P15
A30: PER SHARE & VALUATION
A31: Market Price per Share (₹) | B31: 688.15 | C31: 495.1 | D31: 478.85 | E31: 352.3 | F31: 597.8 | G31: 914.75 | H31: 983.1 | I31: 1620.55 | J31: 1734.7 | K31: 1757.2 | L31: =Assumptions!$C$35 | M31: =Assumptions!$C$35 | N31: =Assumptions!$C$35 | O31: =Assumptions!$C$35 | P31: =Assumptions!$C$35
A32: Earnings Per Share (₹) | B32: =IS!B31 | C32: =IS!C31 | D32: =IS!D31 | E32: =IS!E31 | F32: =IS!F31 | G32: =IS!G31 | H32: =IS!H31 | I32: =IS!I31 | ... P32: =IS!P31
A33: P/E Ratio (x) | B33: =B31/B32 | C33: =C31/C32 | D33: =D31/D32 | E33: =E31/E32 | F33: =F31/F32 | G33: =G31/G32 | H33: =H31/H32 | I33: =I31/I32 | ... P33: =P31/P32
A34: Book Value per Share (₹) | B34: =BS!B27 | C34: =BS!C27 | D34: =BS!D27 | E34: =BS!E27 | F34: =BS!F27 | G34: =BS!G27 | H34: =BS!H27 | I34: =BS!I27 | ... P34: =BS!P27
A35: P/B Ratio (x) | B35: =B31/B34 | C35: =C31/C34 | D35: =D31/D34 | E35: =E31/E34 | F35: =F31/F34 | G35: =G31/G34 | H35: =H31/H34 | I35: =I31/I34 | ... P35: =P31/P34
A36: Dividend per Share (₹) | B36: =IS!B32 | C36: =IS!C32 | D36: =IS!D32 | E36: =IS!E32 | F36: =IS!F32 | G36: =IS!G32 | H36: =IS!H32 | I36: =IS!I32 | ... P36: =IS!P32
A37: Dividend Yield % | B37: =B36/B31 | C37: =C36/C31 | D37: =D36/D31 | E37: =E36/E31 | F37: =F36/F31 | G37: =G36/G31 | H37: =H36/H31 | I37: =I36/I31 | ... P37: =P36/P31
A38: EV / EBITDA (x) | B38: =(B31*IS!B30+BS!B18-BS!B11-BS!B8)/IS!B15 | C38: =(C31*IS!C30+BS!C18-BS!C11-BS!C8)/IS!C15 | D38: =(D31*IS!D30+BS!D18-BS!D11-BS!D8)/IS!D15 | E38: =(E31*IS!E30+BS!E18-BS!E11-BS!E8)/IS!E15 | F38: =(F31*IS!F30+BS!F18-BS!F11-BS!F8)/IS!F15 | G38: =(G31*IS!G30+BS!G18-BS!G11-BS!G8)/IS!G15 | H38: =(H31*IS!H30+BS!H18-BS!H11-BS!H8)/IS!H15 | I38: =(I31*IS!I30+BS!I18-BS!I11-BS!I8)/IS!I15 | ... P38: =(P31*IS!P30+BS!P18-BS!P11-BS!P8)/IS!P15

Sheet DCF
A1: DCF Valuation — Free Cash Flow to Firm (FCFF)
A2: SUN PHARMACEUTICAL INDUSTRIES LTD (Consolidated)
A4: FREE CASH FLOW TO FIRM PROJECTION
A5: (₹ Crore, unless stated otherwise) | B5: FY2017 | C5: FY2018 | D5: FY2019 | E5: FY2020 | F5: FY2021 | G5: FY2022 | H5: FY2023 | I5: FY2024 | J5: FY2025 | K5: FY2026 | L5: FY2027E | M5: FY2028E | N5: FY2029E | O5: FY2030E | P5: FY2031E
A6: EBIT | B6: =IS!B19 | C6: =IS!C19 | D6: =IS!D19 | E6: =IS!E19 | F6: =IS!F19 | G6: =IS!G19 | H6: =IS!H19 | I6: =IS!I19 | ... P6: =IS!P19
A7: Less: Taxes on EBIT (at effective tax rate) | B7: =-B6*IS!B23 | C7: =-C6*IS!C23 | D7: =-D6*IS!D23 | E7: =-E6*IS!E23 | F7: =-F6*IS!F23 | G7: =-G6*IS!G23 | H7: =-H6*IS!H23 | I7: =-I6*IS!I23 | ... P7: =-P6*IS!P23
A8: NOPAT (Tax-Effected EBIT) | B8: =B6+B7 | C8: =C6+C7 | D8: =D6+D7 | E8: =E6+E7 | F8: =F6+F7 | G8: =G6+G7 | H8: =H6+H7 | I8: =I6+I7 | ... P8: =P6+P7
A9: Add: Depreciation & Amortization | B9: =IS!B18 | C9: =IS!C18 | D9: =IS!D18 | E9: =IS!E18 | F9: =IS!F18 | G9: =IS!G18 | H9: =IS!H18 | I9: =IS!I18 | ... P9: =IS!P18
A10: Less: Capital Expenditure | B10: n/a | C10: =CF!C22 | D10: =CF!D22 | E10: =CF!E22 | F10: =CF!F22 | G10: =CF!G22 | H10: =CF!H22 | I10: =CF!I22 | J10: =CF!J22 | ... P10: =CF!P22
A11: Less: Increase in Net Working Capital | B11: n/a | C11: =-(BS!C25-BS!B25) | D11: =-(BS!D25-BS!C25) | E11: =-(BS!E25-BS!D25) | F11: =-(BS!F25-BS!E25) | G11: =-(BS!G25-BS!F25) | H11: =-(BS!H25-BS!G25) | I11: =-(BS!I25-BS!H25) | J11: =-(BS!J25-BS!I25) | ... P11: =-(BS!P25-BS!O25)
A12: Free Cash Flow to Firm (FCFF) | B12: n/a | C12: =C8+C9+C10+C11 | D12: =D8+D9+D10+D11 | E12: =E8+E9+E10+E11 | F12: =F8+F9+F10+F11 | G12: =G8+G9+G10+G11 | H12: =H8+H9+H10+H11 | I12: =I8+I9+I10+I11 | J12: =J8+J9+J10+J11 | ... P12: =P8+P9+P10+P11
A14: DISCOUNTING — PROJECTION PERIOD (FY2027E–FY2031E)
A15: Discount period (n, years) | L15: 1 | M15: 2 | N15: 3 | O15: 4 | P15: 5
A16: FCFF (₹ Cr) | L16: =L12 | M16: =M12 | N16: =N12 | O16: =O12 | P16: =P12
A17: Discount Factor @ WACC | L17: =1/(1+Assumptions!$C$30)^L15 | M17: =1/(1+Assumptions!$C$30)^M15 | N17: =1/(1+Assumptions!$C$30)^N15 | O17: =1/(1+Assumptions!$C$30)^O15 | P17: =1/(1+Assumptions!$C$30)^P15
A18: Present Value of FCFF | L18: =L16*L17 | M18: =M16*M17 | N18: =N16*N17 | O18: =O16*O17 | P18: =P16*P17
A20: TERMINAL VALUE (GORDON GROWTH)
A21: Terminal Year FCFF (FY2031E) | C21: =P16
A22: Terminal Growth Rate (g) | C22: =Assumptions!$C$32
A23: WACC | C23: =Assumptions!$C$30
A24: Terminal Value = FCFF₅×(1+g) / (WACC−g) | C24: =C21*(1+C22)/(C23-C22)
A25: Discount Factor (Year 5) | C25: =P17
A26: Present Value of Terminal Value | C26: =C24*C25
A28: ENTERPRISE VALUE → EQUITY VALUE BRIDGE
A29: Sum of PV of FCFF (FY27E–FY31E) | C29: =SUM(L18:P18)
A30: Add: PV of Terminal Value | C30: =C26
A31: Enterprise Value | C31: =C29+C30
A32: Less: Total Debt (FY2026A) | C32: =-BS!K18
A33: Add: Cash & Bank (FY2026A) | C33: =BS!K11
A34: Add: Investments (FY2026A) | C34: =BS!K8
A35: Equity Value | C35: =C31+C32+C33+C34
A36: Shares Outstanding (Cr) | C36: =Assumptions!$C$37
A37: Intrinsic Value per Share (₹) | C37: =C35/C36
A38: Current Market Price (₹) | C38: =Assumptions!$C$35
A39: Upside / (Downside) % | C39: =C37/C38-1
A41: SENSITIVITY ANALYSIS — INTRINSIC VALUE PER SHARE (₹)
A42: WACC (↓) \ Terminal Growth (→)
C43: =$C$22+-0.01 | D43: =$C$22+-0.005 | E43: =$C$22+0 | F43: =$C$22+0.005 | G43: =$C$22+0.01
B44: =$C$23+-0.01 | C44: =(SUMPRODUCT($L$16:$P$16,1/(1+$B44)^$L$15:$P$15)+($P$16*(1+C$43)/($B44-C$43))/(1+$B44)^$P$15+$C$32+$C$33+$C$34)/$C$36 | D44: =(SUMPRODUCT($L$16:$P$16,1/(1+$B44)^$L$15:$P$15)+($P$16*(1+D$43)/($B44-D$43))/(1+$B44)^$P$15+$C$32+$C$33+$C$34)/$C$36 | E44: =(SUMPRODUCT($L$16:$P$16,1/(1+$B44)^$L$15:$P$15)+($P$16*(1+E$43)/($B44-E$43))/(1+$B44)^$P$15+$C$32+$C$33+$C$34)/$C$36 | F44: =(SUMPRODUCT($L$16:$P$16,1/(1+$B44)^$L$15:$P$15)+($P$16*(1+F$43)/($B44-F$43))/(1+$B44)^$P$15+$C$32+$C$33+$C$34)/$C$36 | G44: =(SUMPRODUCT($L$16:$P$16,1/(1+$B44)^$L$15:$P$15)+($P$16*(1+G$43)/($B44-G$43))/(1+$B44)^$P$15+$C$32+$C$33+$C$34)/$C$36
B45: =$C$23+-0.005 | C45: =(SUMPRODUCT($L$16:$P$16,1/(1+$B45)^$L$15:$P$15)+($P$16*(1+C$43)/($B45-C$43))/(1+$B45)^$P$15+$C$32+$C$33+$C$34)/$C$36 | D45: =(SUMPRODUCT($L$16:$P$16,1/(1+$B45)^$L$15:$P$15)+($P$16*(1+D$43)/($B45-D$43))/(1+$B45)^$P$15+$C$32+$C$33+$C$34)/$C$36 | E45: =(SUMPRODUCT($L$16:$P$16,1/(1+$B45)^$L$15:$P$15)+($P$16*(1+E$43)/($B45-E$43))/(1+$B45)^$P$15+$C$32+$C$33+$C$34)/$C$36 | F45: =(SUMPRODUCT($L$16:$P$16,1/(1+$B45)^$L$15:$P$15)+($P$16*(1+F$43)/($B45-F$43))/(1+$B45)^$P$15+$C$32+$C$33+$C$34)/$C$36 | G45: =(SUMPRODUCT($L$16:$P$16,1/(1+$B45)^$L$15:$P$15)+($P$16*(1+G$43)/($B45-G$43))/(1+$B45)^$P$15+$C$32+$C$33+$C$34)/$C$36
...

Sheet Comps
A1: Relative Valuation — Peer Comparison
A2: Trailing multiples, Health Technology (Nifty Pharma) peer set
A4: PEER TRADING MULTIPLES (TRAILING)
A5: Company | B5: Mkt Cap (₹ Cr) | C5: P/E (x) | D5: EV/EBITDA (x) | E5: P/B (x) | F5: ROE %
A6: SUN PHARMACEUTICAL INDUSTRIES LTD | B6: =Assumptions!C36 | C6: =Ratios!K33 | D6: =Ratios!K38 | E6: =Ratios!K35 | F6: =Ratios!K15
A7: Dr. Reddy's Laboratories Limited (DRREDDY) | B7: 102106 | C7: 23.589995 | D7: 14.695 | E7: 2.6747696 | F7: 0.1206
A8: Cipla Limited (CIPLA) | B8: 115477 | C8: 29.55625 | D8: 18.142 | E8: 3.3283076 | F8: 0.1182
A10: Peer Average (excl. SUN PHARMACEUTICAL INDUSTRIES LTD) | B10: =IFERROR(AVERAGE(B7:B9),"n/a") | C10: =IFERROR(AVERAGE(C7:C9),"n/a") | D10: =IFERROR(AVERAGE(D7:D9),"n/a") | E10: =IFERROR(AVERAGE(E7:E9),"n/a") | F10: =IFERROR(AVERAGE(F7:F9),"n/a")
A12: IMPLIED VALUATION — SUN PHARMACEUTICAL INDUSTRIES LTD AT PEER-AVERAGE MULTIPLES
A13: Basis | B13: Multiple (x) | C13: SUN PHARMACEUTICAL INDUSTRIES LTD Metric (FY2026A, ₹ Cr) | D13: Implied Value
A14: P/E × FY2026A EPS | B14: =C10 | C14: =IS!K31 | D14: =IFERROR(B14*C14,"Enter peer data")
A15: EV/EBITDA × FY2026A EBITDA (→ per share) | B15: =D10 | C15: =IS!K15 | D15: =IFERROR((B15*C15-BS!K18+BS!K11+BS!K8)/Assumptions!$C$37,"Enter peer data")
A17: Current Market Price (₹) | D17: =Assumptions!$C$35
A18: DCF Intrinsic Value (₹) — see DCF sheet | D18: =DCF!C37

Sheet Dashboard
A1: SUN PHARMACEUTICAL INDUSTRIES LTD — VALUATION DASHBOARD
A2: Summary of Key Outputs
A4: VALUATION SUMMARY (₹ per share)
A5: Current Market Price | C5: =Assumptions!$C$35
A6: DCF Intrinsic Value (Base Case) | C6: =DCF!C37
A7: Implied Value — Peer P/E | C7: =Comps!D14
A8: Implied Value — Peer EV/EBITDA | C8: =Comps!D15
A9: DCF Upside / (Downside) vs. CMP | C9: =C6/C5-1
A11: KEY OPERATING METRICS (FY2026A vs. FY2031E)
A12: Metric | B12: FY2026A | C12: FY2031E
A13: Revenue (₹ Cr) | B13: =IS!K6 | C13: =IS!P6
A14: EBITDA (₹ Cr) | B14: =IS!K15 | C14: =IS!P15
A15: EBITDA Margin % | B15: =IS!K16 | C15: =IS!P16
A16: Net Profit (₹ Cr) | B16: =IS!K24 | C16: =IS!P24
A17: EPS (₹) | B17: =IS!K31 | C17: =IS!P31
A18: ROE % | B18: =Ratios!K15 | C18: =Ratios!P15
A19: Revenue CAGR FY2026A–FY2031E | C19: =(IS!P6/IS!K6)^(1/5)-1
A21: REVENUE & EBITDA TREND (₹ CRORE)
A22: (chart below — historical FY2017 to projected FY2031E)
